Workbook

Sheet 5mini - 5.4mini
A1: gpt-5-mini (low) → gpt-5.4-mini (low)
A4: Task | B4: Off score | C4: Off regens | D4: Off total time (min) | E4: Off cost (USD) | F4: On score | G4: On regens | H4: On total time (min) | I4: On cost (USD) | J4: Effect
A5: easy-001 | B5: 5/6 | C5: 0 | D5: 11.4 | E5: 0.0021295 | F5: 5/6 | G5: 0 | H5: 11.4 | I5: 0.0056755 | J5: =IFERROR(VALUE(LEFT(F5,FIND("/",F5)-1))-VALUE(LEFT(B5,FIND("/",B5)-1)),"N/A") -> 0
A6: easy-002 | B6: 6/6 | C6: 0 | D6: 9.6 | E6: 0.00097675 | F6: 6/6 | G6: 0 | H6: 9.7 | I6: 0.0033115 | J6: =IFERROR(VALUE(LEFT(F6,FIND("/",F6)-1))-VALUE(LEFT(B6,FIND("/",B6)-1)),"N/A") -> 0
A7: easy-003 | B7: 6/6 | C7: 0 | D7: 10.5 | E7: 0.000614875 | F7: 6/6 | G7: 0 | H7: 9.8 | I7: 0.002299375 | J7: =IFERROR(VALUE(LEFT(F7,FIND("/",F7)-1))-VALUE(LEFT(B7,FIND("/",B7)-1)),"N/A") -> 0
A8: easy-004 | B8: 4/6 | C8: 0 | D8: 10.8 | E8: 0.000976125 | F8: 5/6 | G8: 1 | H8: 11.1 | I8: 0.010275625 | J8: =IFERROR(VALUE(LEFT(F8,FIND("/",F8)-1))-VALUE(LEFT(B8,FIND("/",B8)-1)),"N/A") -> 1
A9: easy-005 | B9: 4/6 | C9: 0 | D9: 10.6 | E9: 0.002213875 | F9: 6/6 | G9: 1 | H9: 11 | I9: 0.011881625 | J9: =IFERROR(VALUE(LEFT(F9,FIND("/",F9)-1))-VALUE(LEFT(B9,FIND("/",B9)-1)),"N/A") -> 2
A10: medium-001 | B10: 10/10 | C10: 0 | D10: 14.7 | E10: 0.00159225 | F10: 10/10 | G10: 0 | H10: 15.2 | I10: 0.005562 | J10: =IFERROR(VALUE(LEFT(F10,FIND("/",F10)-1))-VALUE(LEFT(B10,FIND("/",B10)-1)),"N/A") -> 0
A11: medium-002 | B11: 9/10 | C11: 0 | D11: 10.2 | E11: 0.00125425 | F11: 10/10 | G11: 1 | H11: 10.8 | I11: 0.0100604 | J11: =IFERROR(VALUE(LEFT(F11,FIND("/",F11)-1))-VALUE(LEFT(B11,FIND("/",B11)-1)),"N/A") -> 1
A12: medium-003 | B12: 10/10 | C12: 0 | D12: 11.8 | E12: 0.00161175 | F12: 10/10 | G12: 0 | H12: 11.8 | I12: 0.0055065 | J12: =IFERROR(VALUE(LEFT(F12,FIND("/",F12)-1))-VALUE(LEFT(B12,FIND("/",B12)-1)),"N/A") -> 0
A13: medium-004 | B13: 6/9 | C13: 0 | D13: 11.4 | E13: 0.001621 | F13: 9/9 | G13: 1 | H13: 12.3 | I13: 0.01426615 | J13: =IFERROR(VALUE(LEFT(F13,FIND("/",F13)-1))-VALUE(LEFT(B13,FIND("/",B13)-1)),"N/A") -> 3
A14: medium-005 | B14: 9/10 | C14: 0 | D14: 11.9 | E14: 0.001886625 | F14: 10/10 | G14: 1 | H14: 13.5 | I14: 0.013977775 | J14: =IFERROR(VALUE(LEFT(F14,FIND("/",F14)-1))-VALUE(LEFT(B14,FIND("/",B14)-1)),"N/A") -> 1
A15: hard-001 | B15: 10/14 | C15: 0 | D15: 13.9 | E15: 0.002246375 | F15: 13/14 | G15: 1 | H15: 15.8 | I15: 0.014675775 | J15: =IFERROR(VALUE(LEFT(F15,FIND("/",F15)-1))-VALUE(LEFT(B15,FIND("/",B15)-1)),"N/A") -> 3
A16: hard-002 | B16: 11/14 | C16: 0 | D16: 13.4 | E16: 0.002767125 | F16: 11/14 | G16: 0 | H16: 13.7 | I16: 0.011567625 | J16: =IFERROR(VALUE(LEFT(F16,FIND("/",F16)-1))-VALUE(LEFT(B16,FIND("/",B16)-1)),"N/A") -> 0
... A19: hard-005 | B19: not reached | C19: 5 | D19: 43.1 | E19: 0.048179525 | F19: 10/14 | G19: 4 | H19: 28.1 | I19: 0.082714675 | J19: =IFERROR(VALUE(LEFT(F19,FIND("/",F19)-1))-VALUE(LEFT(B19,FIND("/",B19)-1)),"N/A") -> N/A
A20: TOTAL | B20: 109/135 (1 not reached) | C20: =SUM(C5:C19) -> 6 | D20: =SUM(D5:D19) -> 220.1 | E20: =SUM(E5:E19) -> 0.08389765 | F20: 130/149 | G20: =SUM(G5:G19) -> 15 | H20: =SUM(H5:H19) -> 229.2 | I20: =SUM(I5:I19) -> 0.29954375 | J20: =SUM(J5:J19) -> 11

Sheet 5.4mini - 5.4mini
A1: gpt-5.4-mini (low) → gpt-5.4-mini (low)
A4: Task | B4: Off score | C4: Off regens | D4: Off total time (min) | E4: Off cost (USD) | F4: On score | G4: On regens | H4: On total time (min) | I4: On cost (USD) | J4: Effect
A5: easy-001 | B5: 6/6 | C5: 0 | D5: 11.1 | E5: 0.0028005 | F5: 6/6 | G5: 0 | H5: 11.6 | I5: 0.0054615 | J5: =IFERROR(VALUE(LEFT(F5,FIND("/",F5)-1))-VALUE(LEFT(B5,FIND("/",B5)-1)),"N/A") -> 0
A6: easy-002 | B6: 6/6 | C6: 0 | D6: 9.7 | E6: 0.00155025 | F6: 6/6 | G6: 0 | H6: 9.7 | I6: 0.00364125 | J6: =IFERROR(VALUE(LEFT(F6,FIND("/",F6)-1))-VALUE(LEFT(B6,FIND("/",B6)-1)),"N/A") -> 0
A7: easy-003 | B7: 6/6 | C7: 0 | D7: 9.7 | E7: 0.001122 | F7: 6/6 | G7: 0 | H7: 9.8 | I7: 0.00264075 | J7: =IFERROR(VALUE(LEFT(F7,FIND("/",F7)-1))-VALUE(LEFT(B7,FIND("/",B7)-1)),"N/A") -> 0
A8: easy-004 | B8: 6/6 | C8: 0 | D8: 11.1 | E8: 0.001633125 | F8: 6/6 | G8: 0 | H8: 11 | I8: 0.003583875 | J8: =IFERROR(VALUE(LEFT(F8,FIND("/",F8)-1))-VALUE(LEFT(B8,FIND("/",B8)-1)),"N/A") -> 0
A9: easy-005 | B9: 6/6 | C9: 0 | D9: 10.6 | E9: 0.002227125 | F9: 6/6 | G9: 0 | H9: 10.7 | I9: 0.004778625 | J9: =IFERROR(VALUE(LEFT(F9,FIND("/",F9)-1))-VALUE(LEFT(B9,FIND("/",B9)-1)),"N/A") -> 0
A10: medium-001 | B10: 10/10 | C10: 1 | D10: 22.6 | E10: 0.009137625 | F10: 10/10 | G10: 1 | H10: 22.1 | I10: 0.014971425 | J10: =IFERROR(VALUE(LEFT(F10,FIND("/",F10)-1))-VALUE(LEFT(B10,FIND("/",B10)-1)),"N/A") -> 0
A11: medium-002 | B11: 10/10 | C11: 0 | D11: 10.4 | E11: 0.002128875 | F11: 10/10 | G11: 0 | H11: 10.9 | I11: 0.004962375 | J11: =IFERROR(VALUE(LEFT(F11,FIND("/",F11)-1))-VALUE(LEFT(B11,FIND("/",B11)-1)),"N/A") -> 0
A12: medium-003 | B12: 10/10 | C12: 0 | D12: 11.8 | E12: 0.003047625 | F12: 10/10 | G12: 0 | H12: 11.8 | I12: 0.006053625 | J12: =IFERROR(VALUE(LEFT(F12,FIND("/",F12)-1))-VALUE(LEFT(B12,FIND("/",B12)-1)),"N/A") -> 0
A13: medium-004 | B13: 7/9 | C13: 0 | D13: 12.1 | E13: 0.003484875 | F13: 7/9 | G13: 0 | H13: 12.1 | I13: 0.007822875 | J13: =IFERROR(VALUE(LEFT(F13,FIND("/",F13)-1))-VALUE(LEFT(B13,FIND("/",B13)-1)),"N/A") -> 0
A14: medium-005 | B14: 10/10 | C14: 0 | D14: 12.9 | E14: 0.003252375 | F14: 10/10 | G14: 0 | H14: 12.9 | I14: 0.007181625 | J14: =IFERROR(VALUE(LEFT(F14,FIND("/",F14)-1))-VALUE(LEFT(B14,FIND("/",B14)-1)),"N/A") -> 0
A15: hard-001 | B15: 13/14 | C15: 0 | D15: 16 | E15: 0.00401775 | F15: 13/14 | G15: 0 | H15: 16 | I15: 0.008664 | J15: =IFERROR(VALUE(LEFT(F15,FIND("/",F15)-1))-VALUE(LEFT(B15,FIND("/",B15)-1)),"N/A") -> 0
A16: hard-002 | B16: 12/14 | C16: 0 | D16: 13.3 | E16: 0.006034125 | F16: 12/14 | G16: 0 | H16: 13.2 | I16: 0.014443125 | J16: =IFERROR(VALUE(LEFT(F16,FIND("/",F16)-1))-VALUE(LEFT(B16,FIND("/",B16)-1)),"N/A") -> 0
... A19: hard-005 | B19: 9/14 | C19: 0 | D19: 13.7 | E19: 0.008788875 | F19: 9/14 | G19: 0 | H19: 13.9 | I19: 0.021240375 | J19: =IFERROR(VALUE(LEFT(F19,FIND("/",F19)-1))-VALUE(LEFT(B19,FIND("/",B19)-1)),"N/A") -> 0
A20: TOTAL | B20: 130/149 | C20: =SUM(C5:C19) -> 1 | D20: =SUM(D5:D19) -> 191.8 | E20: =SUM(E5:E19) -> 0.063906375 | F20: 132/149 | G20: =SUM(G5:G19) -> 2 | H20: =SUM(H5:H19) -> 193.1 | I20: =SUM(I5:I19) -> 0.15765308 | J20: =SUM(J5:J19) -> 2

Sheet 5.4mini - 5.6sol
A1: gpt-5.4-mini (low) → gpt-5.6-sol (medium)
A4: Task | B4: Off score | C4: Off regens | D4: Off total time (min) | E4: Off cost (USD) | F4: On score | G4: On regens | H4: On total time (min) | I4: On cost (USD) | J4: Effect
A5: easy-001 | B5: 6/6 | C5: 0 | D5: 11.1 | E5: 0.0028005 | F5: 6/6 | G5: 0 | H5: 12.9 | I5: 0.009089 | J5: =IFERROR(VALUE(LEFT(F5,FIND("/",F5)-1))-VALUE(LEFT(B5,FIND("/",B5)-1)),"N/A") -> 0
A6: easy-002 | B6: 6/6 | C6: 0 | D6: 9.7 | E6: 0.00155025 | F6: 6/6 | G6: 0 | H6: 9.8 | I6: 0.00510825 | J6: =IFERROR(VALUE(LEFT(F6,FIND("/",F6)-1))-VALUE(LEFT(B6,FIND("/",B6)-1)),"N/A") -> 0
A7: easy-003 | B7: 6/6 | C7: 0 | D7: 9.7 | E7: 0.001122 | F7: 6/6 | G7: 0 | H7: 9.8 | I7: 0.00272 | J7: =IFERROR(VALUE(LEFT(F7,FIND("/",F7)-1))-VALUE(LEFT(B7,FIND("/",B7)-1)),"N/A") -> 0
A8: easy-004 | B8: 6/6 | C8: 0 | D8: 11.1 | E8: 0.001633125 | F8: 6/6 | G8: 0 | H8: 10.8 | I8: 0.004703625 | J8: =IFERROR(VALUE(LEFT(F8,FIND("/",F8)-1))-VALUE(LEFT(B8,FIND("/",B8)-1)),"N/A") -> 0
A9: easy-005 | B9: 6/6 | C9: 0 | D9: 10.6 | E9: 0.002227125 | F9: 6/6 | G9: 0 | H9: 10.6 | I9: 0.007195125 | J9: =IFERROR(VALUE(LEFT(F9,FIND("/",F9)-1))-VALUE(LEFT(B9,FIND("/",B9)-1)),"N/A") -> 0
A10: medium-001 | B10: 10/10 | C10: 1 | D10: 22.6 | E10: 0.009137625 | F10: 10/10 | G10: 1 | H10: 15.9 | I10: 0.021149875 | J10: =IFERROR(VALUE(LEFT(F10,FIND("/",F10)-1))-VALUE(LEFT(B10,FIND("/",B10)-1)),"N/A") -> 0
A11: medium-002 | B11: 10/10 | C11: 0 | D11: 10.4 | E11: 0.002128875 | F11: 10/10 | G11: 0 | H11: 10.7 | I11: 0.006909375 | J11: =IFERROR(VALUE(LEFT(F11,FIND("/",F11)-1))-VALUE(LEFT(B11,FIND("/",B11)-1)),"N/A") -> 0
A12: medium-003 | B12: 10/10 | C12: 0 | D12: 11.8 | E12: 0.003047625 | F12: 10/10 | G12: 0 | H12: 11.8 | I12: 0.009648125 | J12: =IFERROR(VALUE(LEFT(F12,FIND("/",F12)-1))-VALUE(LEFT(B12,FIND("/",B12)-1)),"N/A") -> 0
A13: medium-004 | B13: 7/9 | C13: 0 | D13: 12.1 | E13: 0.003484875 | F13: 9/9 | G13: 1 | H13: 12.4 | I13: 0.023496875 | J13: =IFERROR(VALUE(LEFT(F13,FIND("/",F13)-1))-VALUE(LEFT(B13,FIND("/",B13)-1)),"N/A") -> 2
A14: medium-005 | B14: 10/10 | C14: 0 | D14: 12.9 | E14: 0.003252375 | F14: 10/10 | G14: 0 | H14: 13 | I14: 0.010437875 | J14: =IFERROR(VALUE(LEFT(F14,FIND("/",F14)-1))-VALUE(LEFT(B14,FIND("/",B14)-1)),"N/A") -> 0
A15: hard-001 | B15: 13/14 | C15: 0 | D15: 16 | E15: 0.00401775 | F15: 14/14 | G15: 1 | H15: 17.4 | I15: 0.03673825 | J15: =IFERROR(VALUE(LEFT(F15,FIND("/",F15)-1))-VALUE(LEFT(B15,FIND("/",B15)-1)),"N/A") -> 1
A16: hard-002 | B16: 12/14 | C16: 0 | D16: 13.3 | E16: 0.006034125 | F16: 14/14 | G16: 0 | H16: 14.4 | I16: 0.022202125 | J16: =IFERROR(VALUE(LEFT(F16,FIND("/",F16)-1))-VALUE(LEFT(B16,FIND("/",B16)-1)),"N/A") -> 2
... A19: hard-005 | B19: 9/14 | C19: 0 | D19: 13.7 | E19: 0.008788875 | F19: 12/14 | G19: 1 | H19: 17.1 | I19: 0.074557375 | J19: =IFERROR(VALUE(LEFT(F19,FIND("/",F19)-1))-VALUE(LEFT(B19,FIND("/",B19)-1)),"N/A") -> 3
A20: TOTAL | B20: 130/149 | C20: =SUM(C5:C19) -> 1 | D20: =SUM(D5:D19) -> 191.8 | E20: =SUM(E5:E19) -> 0.063906375 | F20: 143/149 | G20: =SUM(G5:G19) -> 6 | H20: =SUM(H5:H19) -> 196.7 | I20: =SUM(I5:I19) -> 0.35088662 | J20: =SUM(J5:J19) -> 13

Sheet Haiku4.5 - Sonnet5
A1: claude-haiku-4.5 (medium) → claude-sonnet-5 (medium)
A4: Task | B4: Off score | C4: Off regens | D4: Off total time (min) | E4: Off cost (USD) | F4: On score | G4: On regens | H4: On total time (min) | I4: On cost (USD) | J4: Effect
A5: easy-001 | B5: 6/6 | C5: 0 | D5: 13.4 | E5: 0.023173 | F5: 6/6 | G5: 0 | H5: 12.7 | I5: 0.030587 | J5: =IFERROR(VALUE(LEFT(F5,FIND("/",F5)-1))-VALUE(LEFT(B5,FIND("/",B5)-1)),"N/A") -> 0
A6: easy-002 | B6: 6/6 | C6: 0 | D6: 10.4 | E6: 0.017086 | F6: 6/6 | G6: 0 | H6: 10.5 | I6: 0.023974 | J6: =IFERROR(VALUE(LEFT(F6,FIND("/",F6)-1))-VALUE(LEFT(B6,FIND("/",B6)-1)),"N/A") -> 0
A7: easy-003 | B7: 6/6 | C7: 0 | D7: 9.9 | E7: 0.0061705 | F7: 6/6 | G7: 0 | H7: 9.7 | I7: 0.0123965 | J7: =IFERROR(VALUE(LEFT(F7,FIND("/",F7)-1))-VALUE(LEFT(B7,FIND("/",B7)-1)),"N/A") -> 0
A8: easy-004 | B8: 6/6 | C8: 0 | D8: 11.4 | E8: 0.0263025 | F8: 6/6 | G8: 0 | H8: 11.5 | I8: 0.0331145 | J8: =IFERROR(VALUE(LEFT(F8,FIND("/",F8)-1))-VALUE(LEFT(B8,FIND("/",B8)-1)),"N/A") -> 0
A9: easy-005 | B9: 6/6 | C9: 0 | D9: 11 | E9: 0.0225425 | F9: 6/6 | G9: 1 | H9: 12.7 | I9: 0.1011225 | J9: =IFERROR(VALUE(LEFT(F9,FIND("/",F9)-1))-VALUE(LEFT(B9,FIND("/",B9)-1)),"N/A") -> 0
A10: medium-001 | B10: 10/10 | C10: 0 | D10: 16.6 | E10: 0.0462215 | F10: 10/10 | G10: 0 | H10: 16.7 | I10: 0.0592615 | J10: =IFERROR(VALUE(LEFT(F10,FIND("/",F10)-1))-VALUE(LEFT(B10,FIND("/",B10)-1)),"N/A") -> 0
A11: medium-002 | B11: 10/10 | C11: 3 | D11: 31.9 | E11: 0.085607 | F11: 10/10 | G11: 1 | H11: 11.7 | I11: 0.071721 | J11: =IFERROR(VALUE(LEFT(F11,FIND("/",F11)-1))-VALUE(LEFT(B11,FIND("/",B11)-1)),"N/A") -> 0
A12: medium-003 | B12: 10/10 | C12: 0 | D12: 13 | E12: 0.0386375 | F12: 10/10 | G12: 0 | H12: 13.2 | I12: 0.0554755 | J12: =IFERROR(VALUE(LEFT(F12,FIND("/",F12)-1))-VALUE(LEFT(B12,FIND("/",B12)-1)),"N/A") -> 0
A13: medium-004 | B13: 9/9 | C13: 0 | D13: 13.3 | E13: 0.0417665 | F13: 9/9 | G13: 0 | H13: 13.5 | I13: 0.0574265 | J13: =IFERROR(VALUE(LEFT(F13,FIND("/",F13)-1))-VALUE(LEFT(B13,FIND("/",B13)-1)),"N/A") -> 0
A14: medium-005 | B14: 10/10 | C14: 0 | D14: 14.4 | E14: 0.0440755 | F14: 10/10 | G14: 0 | H14: 14.8 | I14: 0.0747615 | J14: =IFERROR(VALUE(LEFT(F14,FIND("/",F14)-1))-VALUE(LEFT(B14,FIND("/",B14)-1)),"N/A") -> 0
A15: hard-001 | B15: 14/14 | C15: 0 | D15: 17.6 | E15: 0.0321385 | F15: 14/14 | G15: 0 | H15: 17.4 | I15: 0.0624485 | J15: =IFERROR(VALUE(LEFT(F15,FIND("/",F15)-1))-VALUE(LEFT(B15,FIND("/",B15)-1)),"N/A") -> 0
A16: hard-002 | B16: 10/14 | C16: 0 | D16: 14.2 | E16: 0.0339885 | F16: 10/14 | G16: 0 | H16: 14.6 | I16: 0.0730485 | J16: =IFERROR(VALUE(LEFT(F16,FIND("/",F16)-1))-VALUE(LEFT(B16,FIND("/",B16)-1)),"N/A") -> 0
... A19: hard-005 | B19: 9/14 | C19: 2 | D19: 33.7 | E19: 0.208769 | F19: 11/14 | G19: 1 | H19: 20.9 | I19: 0.254601 | J19: =IFERROR(VALUE(LEFT(F19,FIND("/",F19)-1))-VALUE(LEFT(B19,FIND("/",B19)-1)),"N/A") -> 2
A20: TOTAL | B20: 135/149 | C20: =SUM(C5:C19) -> 6 | D20: =SUM(D5:D19) -> 251.6 | E20: =SUM(E5:E19) -> 0.804802 | F20: 137/149 | G20: =SUM(G5:G19) -> 5 | H20: =SUM(H5:H19) -> 232.9 | I20: =SUM(I5:I19) -> 1.351965 | J20: =SUM(J5:J19) -> 2

Sheet GLM5.2 - 5.4mini
A1: z-ai/glm-5.2 (high) → gpt-5.4-mini (medium)
A4: Task | B4: Off score | C4: Off regens | D4: Off total time (min) | E4: Off cost (USD) | F4: On score | G4: On regens | H4: On total time (min) | I4: On cost (USD) | J4: Effect
A5: easy-001 | B5: 6/6 | C5: 0 | D5: 12.2 | E5: 0.0102994 | F5: 6/6 | G5: 0 | H5: 12.2 | I5: 0.01856965 | J5: =IFERROR(VALUE(LEFT(F5,FIND("/",F5)-1))-VALUE(LEFT(B5,FIND("/",B5)-1)),"N/A") -> 0
A6: easy-002 | B6: 6/6 | C6: 0 | D6: 9.8 | E6: 0.00318144 | F6: 6/6 | G6: 0 | H6: 9.9 | I6: 0.00687519 | J6: =IFERROR(VALUE(LEFT(F6,FIND("/",F6)-1))-VALUE(LEFT(B6,FIND("/",B6)-1)),"N/A") -> 0
A7: easy-003 | B7: 6/6 | C7: 0 | D7: 9.9 | E7: 0.00336958 | F7: 6/6 | G7: 0 | H7: 10.1 | I7: 0.00565258 | J7: =IFERROR(VALUE(LEFT(F7,FIND("/",F7)-1))-VALUE(LEFT(B7,FIND("/",B7)-1)),"N/A") -> 0
A8: easy-004 | B8: 6/6 | C8: 0 | D8: 14.1 | E8: 0.03328298 | F8: 6/6 | G8: 0 | H8: 14.4 | I8: 0.04204073 | J8: =IFERROR(VALUE(LEFT(F8,FIND("/",F8)-1))-VALUE(LEFT(B8,FIND("/",B8)-1)),"N/A") -> 0
A9: easy-005 | B9: 6/6 | C9: 0 | D9: 10.6 | E9: 0.00470534 | F9: 6/6 | G9: 0 | H9: 11 | I9: 0.01360259 | J9: =IFERROR(VALUE(LEFT(F9,FIND("/",F9)-1))-VALUE(LEFT(B9,FIND("/",B9)-1)),"N/A") -> 0
A10: medium-001 | B10: 10/10 | C10: 0 | D10: 19.8 | E10: 0.04296568 | F10: 10/10 | G10: 0 | H10: 19.9 | I10: 0.05285293 | J10: =IFERROR(VALUE(LEFT(F10,FIND("/",F10)-1))-VALUE(LEFT(B10,FIND("/",B10)-1)),"N/A") -> 0
A11: medium-002 | B11: 9/10 | C11: 0 | D11: 11 | E11: 0.00900364 | F11: 9/10 | G11: 0 | H11: 11.3 | I11: 0.01844989 | J11: =IFERROR(VALUE(LEFT(F11,FIND("/",F11)-1))-VALUE(LEFT(B11,FIND("/",B11)-1)),"N/A") -> 0
A12: medium-003 | B12: 10/10 | C12: 0 | D12: 14.4 | E12: 0.02617334 | F12: 10/10 | G12: 0 | H12: 14.7 | I12: 0.03650534 | J12: =IFERROR(VALUE(LEFT(F12,FIND("/",F12)-1))-VALUE(LEFT(B12,FIND("/",B12)-1)),"N/A") -> 0
A13: medium-004 | B13: 9/9 | C13: 0 | D13: 15.4 | E13: 0.03180414 | F13: 9/9 | G13: 0 | H13: 15.3 | I13: 0.04455414 | J13: =IFERROR(VALUE(LEFT(F13,FIND("/",F13)-1))-VALUE(LEFT(B13,FIND("/",B13)-1)),"N/A") -> 0
A14: medium-005 | B14: 10/10 | C14: 0 | D14: 19.4 | E14: 0.06523314 | F14: 10/10 | G14: 0 | H14: 20.2 | I14: 0.07580439 | J14: =IFERROR(VALUE(LEFT(F14,FIND("/",F14)-1))-VALUE(LEFT(B14,FIND("/",B14)-1)),"N/A") -> 0
A15: hard-001 | B15: 14/14 | C15: 0 | D15: 19.4 | E15: 0.0305376 | F15: 14/14 | G15: 0 | H15: 19.1 | I15: 0.04327335 | J15: =IFERROR(VALUE(LEFT(F15,FIND("/",F15)-1))-VALUE(LEFT(B15,FIND("/",B15)-1)),"N/A") -> 0
A16: hard-002 | B16: 14/14 | C16: 0 | D16: 18.2 | E16: 0.04727524 | F16: 14/14 | G16: 0 | H16: 19.1 | I16: 0.07522774 | J16: =IFERROR(VALUE(LEFT(F16,FIND("/",F16)-1))-VALUE(LEFT(B16,FIND("/",B16)-1)),"N/A") -> 0
... A19: hard-005 | B19: 11/14 | C19: 1 | D19: 35.3 | E19: 0.1867372 | F19: 12/14 | G19: 1 | H19: 33.3 | I19: 0.30751665 | J19: =IFERROR(VALUE(LEFT(F19,FIND("/",F19)-1))-VALUE(LEFT(B19,FIND("/",B19)-1)),"N/A") -> 1
A20: TOTAL | B20: 140/149 | C20: =SUM(C5:C19) -> 1 | D20: =SUM(D5:D19) -> 252.9 | E20: =SUM(E5:E19) -> 0.64373116 | F20: 141/149 | G20: =SUM(G5:G19) -> 1 | H20: =SUM(H5:H19) -> 255.6 | I20: =SUM(I5:I19) -> 0.95337336 | J20: =SUM(J5:J19) -> 1

Sheet Gemma4 - 5.6luna
A1: google/gemma-4-26b-a4b-it (medium) → gpt-5.6-luna (medium)
A4: Task | B4: Off score | C4: Off regens | D4: Off total time (min) | E4: Off cost (USD) | F4: On score | G4: On regens | H4: On total time (min) | I4: On cost (USD) | J4: Effect
A5: easy-001 | B5: 5/6 | C5: 0 | D5: 13.8 | E5: 0.000882655 | F5: 5/6 | G5: 0 | H5: 13.8 | I5: 0.001728305 | J5: =IFERROR(VALUE(LEFT(F5,FIND("/",F5)-1))-VALUE(LEFT(B5,FIND("/",B5)-1)),"N/A") -> 0
A6: easy-002 | B6: 6/6 | C6: 0 | D6: 11.4 | E6: 0.00097348 | F6: 6/6 | G6: 0 | H6: 11.4 | I6: 0.00158703 | J6: =IFERROR(VALUE(LEFT(F6,FIND("/",F6)-1))-VALUE(LEFT(B6,FIND("/",B6)-1)),"N/A") -> 0
A7: easy-003 | B7: 6/6 | C7: 0 | D7: 10.3 | E7: 0.000318215 | F7: 6/6 | G7: 0 | H7: 10.2 | I7: 0.000589715 | J7: =IFERROR(VALUE(LEFT(F7,FIND("/",F7)-1))-VALUE(LEFT(B7,FIND("/",B7)-1)),"N/A") -> 0
A8: easy-004 | B8: 5/6 | C8: 0 | D8: 12.1 | E8: 0.000846085 | F8: 5/6 | G8: 0 | H8: 12.4 | I8: 0.001585535 | J8: =IFERROR(VALUE(LEFT(F8,FIND("/",F8)-1))-VALUE(LEFT(B8,FIND("/",B8)-1)),"N/A") -> 0
A9: easy-005 | B9: 6/6 | C9: 0 | D9: 12.5 | E9: 0.00083321 | F9: 6/6 | G9: 0 | H9: 11.7 | I9: 0.00165786 | J9: =IFERROR(VALUE(LEFT(F9,FIND("/",F9)-1))-VALUE(LEFT(B9,FIND("/",B9)-1)),"N/A") -> 0
A10: medium-001 | B10: 8/10 | C10: 0 | D10: 14.2 | E10: 0.001207 | F10: 9/10 | G10: 1 | H10: 15.5 | I10: 0.00495973 | J10: =IFERROR(VALUE(LEFT(F10,FIND("/",F10)-1))-VALUE(LEFT(B10,FIND("/",B10)-1)),"N/A") -> 1
A11: medium-002 | B11: 9/10 | C11: 0 | D11: 12.2 | E11: 0.000783535 | F11: 10/10 | G11: 1 | H11: 13.5 | I11: 0.004526785 | J11: =IFERROR(VALUE(LEFT(F11,FIND("/",F11)-1))-VALUE(LEFT(B11,FIND("/",B11)-1)),"N/A") -> 1
A12: medium-003 | B12: 9/10 | C12: 0 | D12: 13.7 | E12: 0.000874565 | F12: 9/10 | G12: 0 | H12: 14.1 | I12: 0.001873965 | J12: =IFERROR(VALUE(LEFT(F12,FIND("/",F12)-1))-VALUE(LEFT(B12,FIND("/",B12)-1)),"N/A") -> 0
A13: medium-004 | B13: 9/9 | C13: 0 | D13: 14 | E13: 0.001198255 | F13: 9/9 | G13: 0 | H13: 13.8 | I13: 0.002837105 | J13: =IFERROR(VALUE(LEFT(F13,FIND("/",F13)-1))-VALUE(LEFT(B13,FIND("/",B13)-1)),"N/A") -> 0
A14: medium-005 | B14: 10/10 | C14: 0 | D14: 14.6 | E14: 0.001173595 | F14: 10/10 | G14: 0 | H14: 15 | I14: 0.002233245 | J14: =IFERROR(VALUE(LEFT(F14,FIND("/",F14)-1))-VALUE(LEFT(B14,FIND("/",B14)-1)),"N/A") -> 0
A15: hard-001 | B15: 13/14 | C15: 0 | D15: 15.1 | E15: 0.00119935 | F15: 13/14 | G15: 0 | H15: 15.7 | I15: 0.0031255 | J15: =IFERROR(VALUE(LEFT(F15,FIND("/",F15)-1))-VALUE(LEFT(B15,FIND("/",B15)-1)),"N/A") -> 0
A16: hard-002 | B16: 12/14 | C16: 0 | D16: 16.3 | E16: 0.001343965 | F16: 13/14 | G16: 2 | H16: 24.9 | I16: 0.015098455 | J16: =IFERROR(VALUE(LEFT(F16,FIND("/",F16)-1))-VALUE(LEFT(B16,FIND("/",B16)-1)),"N/A") -> 1
... A19: hard-005 | B19: 9/14 | C19: 1 | D19: 32.3 | E19: 0.00535596 | F19: 10/14 | G19: 1 | H19: 23.4 | I19: 0.01153539 | J19: =IFERROR(VALUE(LEFT(F19,FIND("/",F19)-1))-VALUE(LEFT(B19,FIND("/",B19)-1)),"N/A") -> 1
A20: TOTAL | B20: 128/149 | C20: =SUM(C5:C19) -> 1 | D20: =SUM(D5:D19) -> 233.2 | E20: =SUM(E5:E19) -> 0.02003568 | F20: 133/149 | G20: =SUM(G5:G19) -> 7 | H20: =SUM(H5:H19) -> 246.8 | I20: =SUM(I5:I19) -> 0.07653434 | J20: =SUM(J5:J19) -> 5

Sheet Qwen3.5 9B - 5.6luna
A1: qwen/qwen3.5-9b (medium) → gpt-5.6-luna (medium)
A4: Task | B4: Off score | C4: Off regens | D4: Off total time (min) | E4: Off cost (USD) | F4: On score | G4: On regens | H4: On total time (min) | I4: On cost (USD) | J4: Effect
A5: easy-001 | B5: 3/6 | C5: 3 | D5: 32.8 | E5: 0.00185695 | F5: 5/6 | G5: 1 | H5: 10.9 | I5: 0.00220705 | J5: =IFERROR(VALUE(LEFT(F5,FIND("/",F5)-1))-VALUE(LEFT(B5,FIND("/",B5)-1)),"N/A") -> 2
A6: easy-002 | B6: 6/6 | C6: 0 | D6: 10.3 | E6: 0.000682525 | F6: 6/6 | G6: 0 | H6: 10.6 | I6: 0.001298325 | J6: =IFERROR(VALUE(LEFT(F6,FIND("/",F6)-1))-VALUE(LEFT(B6,FIND("/",B6)-1)),"N/A") -> 0
A7: easy-003 | B7: 5/6 | C7: 0 | D7: 9.5 | E7: 0.0001181 | F7: 5/6 | G7: 0 | H7: 9.6 | I7: 0.0003807 | J7: =IFERROR(VALUE(LEFT(F7,FIND("/",F7)-1))-VALUE(LEFT(B7,FIND("/",B7)-1)),"N/A") -> 0
A8: easy-004 | B8: 5/6 | C8: 0 | D8: 10.7 | E8: 0.0001522 | F8: 5/6 | G8: 0 | H8: 11.2 | I8: 0.0007537 | J8: =IFERROR(VALUE(LEFT(F8,FIND("/",F8)-1))-VALUE(LEFT(B8,FIND("/",B8)-1)),"N/A") -> 0
A9: easy-005 | B9: 5/6 | C9: 0 | D9: 10.6 | E9: 0.000161375 | F9: 6/6 | G9: 1 | H9: 10.8 | I9: 0.002465975 | J9: =IFERROR(VALUE(LEFT(F9,FIND("/",F9)-1))-VALUE(LEFT(B9,FIND("/",B9)-1)),"N/A") -> 1
A10: medium-001 | B10: not reached | C10: 5 | D10: 38.2 | E10: 0.00379295 | F10: not reached | G10: 5 | H10: 11.3 | I10: 0.0134495 | J10: =IFERROR(VALUE(LEFT(F10,FIND("/",F10)-1))-VALUE(LEFT(B10,FIND("/",B10)-1)),"N/A") -> N/A
A11: medium-002 | B11: not reached | C11: 5 | D11: 44.4 | E11: 0.00555215 | F11: not reached | G11: 5 | H11: 17.2 | I11: 0.00958395 | J11: =IFERROR(VALUE(LEFT(F11,FIND("/",F11)-1))-VALUE(LEFT(B11,FIND("/",B11)-1)),"N/A") -> N/A
A12: medium-003 | B12: 7/10 | C12: 1 | D12: 10.3 | E12: 0.00063675 | F12: 7/10 | G12: 2 | H12: 11.1 | I12: 0.0046889 | J12: =IFERROR(VALUE(LEFT(F12,FIND("/",F12)-1))-VALUE(LEFT(B12,FIND("/",B12)-1)),"N/A") -> 0
A13: medium-004 | B13: 8/9 | C13: 2 | D13: 33.4 | E13: 0.002280525 | F13: 8/9 | G13: 1 | H13: 11.9 | I13: 0.003844275 | J13: =IFERROR(VALUE(LEFT(F13,FIND("/",F13)-1))-VALUE(LEFT(B13,FIND("/",B13)-1)),"N/A") -> 0
A14: medium-005 | B14: 5/10 | C14: 3 | D14: 19 | E14: 0.002256675 | F14: 10/10 | G14: 3 | H14: 14.5 | I14: 0.008031175 | J14: =IFERROR(VALUE(LEFT(F14,FIND("/",F14)-1))-VALUE(LEFT(B14,FIND("/",B14)-1)),"N/A") -> 5
A15: hard-001 | B15: 13/14 | C15: 5 | D15: 54.8 | E15: 0.00500945 | F15: not reached | G15: 5 | H15: 2.9 | I15: 0.0146053 | J15: =IFERROR(VALUE(LEFT(F15,FIND("/",F15)-1))-VALUE(LEFT(B15,FIND("/",B15)-1)),"N/A") -> N/A
A16: hard-002 | B16: not reached | C16: 5 | D16: 54.3 | E16: 0.00553255 | F16: not reached | G16: 5 | H16: 14.5 | I16: 0.01779355 | J16: =IFERROR(VALUE(LEFT(F16,FIND("/",F16)-1))-VALUE(LEFT(B16,FIND("/",B16)-1)),"N/A") -> N/A
... A19: hard-005 | B19: not reached | C19: 5 | D19: 43.5 | E19: 0.008911275 | F19: not reached | G19: 5 | H19: 5.1 | I19: 0.024286925 | J19: =IFERROR(VALUE(LEFT(F19,FIND("/",F19)-1))-VALUE(LEFT(B19,FIND("/",B19)-1)),"N/A") -> N/A
A20: TOTAL | B20: 65/87 (5 not reached) | C20: =SUM(C5:C19) -> 40 | D20: =SUM(D5:D19) -> 425 | E20: =SUM(E5:E19) -> 0.046156075 | F20: 63/73 (6 not reached) | G20: =SUM(G5:G19) -> 41 | H20: =SUM(H5:H19) -> 163.2 | I20: =SUM(I5:I19) -> 0.14689923 | J20: =SUM(J5:J19) -> 11

Sheet DeepSeek V4 - 5.6luna
A1: deepseek/deepseek-v4-flash-0731 (high) → gpt-5.6-luna (medium)
A4: Task | B4: Off score | C4: Off regens | D4: Off total time (min) | E4: Off cost (USD) | F4: On score | G4: On regens | H4: On total time (min) | I4: On cost (USD) | J4: Effect
A5: easy-001 | B5: 5/6 | C5: 0 | D5: 11.7 | E5: 0.00051356 | F5: 5/6 | G5: 0 | H5: 11.8 | I5: 0.00140256 | J5: =IFERROR(VALUE(LEFT(F5,FIND("/",F5)-1))-VALUE(LEFT(B5,FIND("/",B5)-1)),"N/A") -> 0
A6: easy-002 | B6: 6/6 | C6: 0 | D6: 9.9 | E6: 0.00015862 | F6: 6/6 | G6: 0 | H6: 10 | I6: 0.00063637 | J6: =IFERROR(VALUE(LEFT(F6,FIND("/",F6)-1))-VALUE(LEFT(B6,FIND("/",B6)-1)),"N/A") -> 0
A7: easy-003 | B7: 6/6 | C7: 0 | D7: 9.8 | E7: 6.4264e-05 | F7: 6/6 | G7: 0 | H7: 9.9 | I7: 0.000323014 | J7: =IFERROR(VALUE(LEFT(F7,FIND("/",F7)-1))-VALUE(LEFT(B7,FIND("/",B7)-1)),"N/A") -> 0
A8: easy-004 | B8: 6/6 | C8: 0 | D8: 12.7 | E8: 0.000552314 | F8: 6/6 | G8: 0 | H8: 12.8 | I8: 0.001583464 | J8: =IFERROR(VALUE(LEFT(F8,FIND("/",F8)-1))-VALUE(LEFT(B8,FIND("/",B8)-1)),"N/A") -> 0
A9: easy-005 | B9: 6/6 | C9: 0 | D9: 11 | E9: 0.000335244 | F9: 6/6 | G9: 0 | H9: 11.3 | I9: 0.001514944 | J9: =IFERROR(VALUE(LEFT(F9,FIND("/",F9)-1))-VALUE(LEFT(B9,FIND("/",B9)-1)),"N/A") -> 0
A10: medium-001 | B10: 10/10 | C10: 0 | D10: 22 | E10: 0.001868104 | F10: 10/10 | G10: 0 | H10: 22.2 | I10: 0.002858254 | J10: =IFERROR(VALUE(LEFT(F10,FIND("/",F10)-1))-VALUE(LEFT(B10,FIND("/",B10)-1)),"N/A") -> 0
A11: medium-002 | B11: 10/10 | C11: 0 | D11: 19.7 | E11: 0.002315364 | F11: 10/10 | G11: 0 | H11: 19.9 | I11: 0.003297164 | J11: =IFERROR(VALUE(LEFT(F11,FIND("/",F11)-1))-VALUE(LEFT(B11,FIND("/",B11)-1)),"N/A") -> 0
A12: medium-003 | B12: 10/10 | C12: 0 | D12: 21.5 | E12: 0.00212563 | F12: 10/10 | G12: 0 | H12: 21.9 | I12: 0.00312503 | J12: =IFERROR(VALUE(LEFT(F12,FIND("/",F12)-1))-VALUE(LEFT(B12,FIND("/",B12)-1)),"N/A") -> 0
A13: medium-004 | B13: 9/9 | C13: 0 | D13: 20.7 | E13: 0.002262744 | F13: 9/9 | G13: 0 | H13: 20.7 | I13: 0.003565694 | J13: =IFERROR(VALUE(LEFT(F13,FIND("/",F13)-1))-VALUE(LEFT(B13,FIND("/",B13)-1)),"N/A") -> 0
A14: medium-005 | B14: 10/10 | C14: 0 | D14: 29.6 | E14: 0.0025374 | F14: 10/10 | G14: 0 | H14: 29.7 | I14: 0.00359955 | J14: =IFERROR(VALUE(LEFT(F14,FIND("/",F14)-1))-VALUE(LEFT(B14,FIND("/",B14)-1)),"N/A") -> 0
A15: hard-001 | B15: 14/14 | C15: 0 | D15: 25.3 | E15: 0.0017454 | F15: 14/14 | G15: 0 | H15: 25.3 | I15: 0.00383995 | J15: =IFERROR(VALUE(LEFT(F15,FIND("/",F15)-1))-VALUE(LEFT(B15,FIND("/",B15)-1)),"N/A") -> 0
A16: hard-002 | B16: 11/14 | C16: 0 | D16: 17.9 | E16: 0.001397404 | F16: 11/14 | G16: 0 | H16: 18.4 | I16: 0.003686604 | J16: =IFERROR(VALUE(LEFT(F16,FIND("/",F16)-1))-VALUE(LEFT(B16,FIND("/",B16)-1)),"N/A") -> 0
... A19: hard-005 | B19: 12/14 | C19: 0 | D19: 24.1 | E19: 0.00307008 | F19: 12/14 | G19: 1 | H19: 26.4 | I19: 0.01183382 | J19: =IFERROR(VALUE(LEFT(F19,FIND("/",F19)-1))-VALUE(LEFT(B19,FIND("/",B19)-1)),"N/A") -> 0
A20: TOTAL | B20: 134/149 | C20: =SUM(C5:C19) -> 1 | D20: =SUM(D5:D19) -> 289.8 | E20: =SUM(E5:E19) -> 0.024598118 | F20: 134/149 | G20: =SUM(G5:G19) -> 2 | H20: =SUM(H5:H19) -> 297.1 | I20: =SUM(I5:I19) -> 0.056284458 | J20: =SUM(J5:J19) -> 0

Sheet Gemma4 - 5.4mini
A1: google/gemma-4-26b-a4b-it (medium) → gpt-5.4-mini (low)
A4: Task | B4: Off score | C4: Off regens | D4: Off total time (min) | E4: Off cost (USD) | F4: On score | G4: On regens | H4: On total time (min) | I4: On cost (USD) | J4: Effect
A5: easy-001 | B5: 5/6 | C5: 0 | D5: 13.8 | E5: 0.000882655 | F5: 5/6 | G5: 0 | H5: 14.4 | I5: 0.005007655 | J5: =IFERROR(VALUE(LEFT(F5,FIND("/",F5)-1))-VALUE(LEFT(B5,FIND("/",B5)-1)),"N/A") -> 0
A6: easy-002 | B6: 6/6 | C6: 0 | D6: 11.4 | E6: 0.00097348 | F6: 6/6 | G6: 0 | H6: 11.4 | I6: 0.00274723 | J6: =IFERROR(VALUE(LEFT(F6,FIND("/",F6)-1))-VALUE(LEFT(B6,FIND("/",B6)-1)),"N/A") -> 0
A7: easy-003 | B7: 6/6 | C7: 0 | D7: 10.3 | E7: 0.000318215 | F7: 6/6 | G7: 0 | H7: 10.6 | I7: 0.001962215 | J7: =IFERROR(VALUE(LEFT(F7,FIND("/",F7)-1))-VALUE(LEFT(B7,FIND("/",B7)-1)),"N/A") -> 0
A8: easy-004 | B8: 5/6 | C8: 0 | D8: 12.1 | E8: 0.000846085 | F8: 5/6 | G8: 0 | H8: 12.4 | I8: 0.003093835 | J8: =IFERROR(VALUE(LEFT(F8,FIND("/",F8)-1))-VALUE(LEFT(B8,FIND("/",B8)-1)),"N/A") -> 0
A9: easy-005 | B9: 6/6 | C9: 0 | D9: 12.5 | E9: 0.00083321 | F9: 6/6 | G9: 0 | H9: 12 | I9: 0.00364871 | J9: =IFERROR(VALUE(LEFT(F9,FIND("/",F9)-1))-VALUE(LEFT(B9,FIND("/",B9)-1)),"N/A") -> 0
A10: medium-001 | B10: 8/10 | C10: 0 | D10: 14.2 | E10: 0.001207 | F10: 8/10 | G10: 0 | H10: 14.5 | I10: 0.00490225 | J10: =IFERROR(VALUE(LEFT(F10,FIND("/",F10)-1))-VALUE(LEFT(B10,FIND("/",B10)-1)),"N/A") -> 0
A11: medium-002 | B11: 9/10 | C11: 0 | D11: 12.2 | E11: 0.000783535 | F11: 10/10 | G11: 3 | H11: 19.8 | I11: 0.018425175 | J11: =IFERROR(VALUE(LEFT(F11,FIND("/",F11)-1))-VALUE(LEFT(B11,FIND("/",B11)-1)),"N/A") -> 1
A12: medium-003 | B12: 9/10 | C12: 0 | D12: 13.7 | E12: 0.000874565 | F12: 9/10 | G12: 0 | H12: 13.9 | I12: 0.004690565 | J12: =IFERROR(VALUE(LEFT(F12,FIND("/",F12)-1))-VALUE(LEFT(B12,FIND("/",B12)-1)),"N/A") -> 0
A13: medium-004 | B13: 9/9 | C13: 0 | D13: 14 | E13: 0.001198255 | F13: 9/9 | G13: 0 | H13: 14.1 | I13: 0.005080255 | J13: =IFERROR(VALUE(LEFT(F13,FIND("/",F13)-1))-VALUE(LEFT(B13,FIND("/",B13)-1)),"N/A") -> 0
A14: medium-005 | B14: 10/10 | C14: 0 | D14: 14.6 | E14: 0.001173595 | F14: 10/10 | G14: 0 | H14: 15 | I14: 0.006020845 | J14: =IFERROR(VALUE(LEFT(F14,FIND("/",F14)-1))-VALUE(LEFT(B14,FIND("/",B14)-1)),"N/A") -> 0
A15: hard-001 | B15: 13/14 | C15: 0 | D15: 15.1 | E15: 0.00119935 | F15: 13/14 | G15: 0 | H15: 15.7 | I15: 0.00575335 | J15: =IFERROR(VALUE(LEFT(F15,FIND("/",F15)-1))-VALUE(LEFT(B15,FIND("/",B15)-1)),"N/A") -> 0
A16: hard-002 | B16: 12/14 | C16: 0 | D16: 16.3 | E16: 0.001343965 | F16: 12/14 | G16: 2 | H16: 24.6 | I16: 0.022883255 | J16: =IFERROR(VALUE(LEFT(F16,FIND("/",F16)-1))-VALUE(LEFT(B16,FIND("/",B16)-1)),"N/A") -> 0
... A19: hard-005 | B19: 9/14 | C19: 1 | D19: 32.3 | E19: 0.00535596 | F19: not reached | G19: 5 | H19: 40.3 | I19: 0.06279024 | J19: =IFERROR(VALUE(LEFT(F19,FIND("/",F19)-1))-VALUE(LEFT(B19,FIND("/",B19)-1)),"N/A") -> N/A
A20: TOTAL | B20: 128/149 | C20: =SUM(C5:C19) -> 1 | D20: =SUM(D5:D19) -> 233.2 | E20: =SUM(E5:E19) -> 0.02003568 | F20: 119/135 (1 not reached) | G20: =SUM(G5:G19) -> 13 | H20: =SUM(H5:H19) -> 274.9 | I20: =SUM(I5:I19) -> 0.19554274 | J20: =SUM(J5:J19) -> 0

Sheet Qwen3.5 9B - 5.4mini
A1: qwen/qwen3.5-9b (medium) → gpt-5.4-mini (low)
A4: Task | B4: Off score | C4: Off regens | D4: Off total time (min) | E4: Off cost (USD) | F4: On score | G4: On regens | H4: On total time (min) | I4: On cost (USD) | J4: Effect
A5: easy-001 | B5: 3/6 | C5: 3 | D5: 32.8 | E5: 0.00185695 | F5: 6/6 | G5: 2 | H5: 12.1 | I5: 0.00747735 | J5: =IFERROR(VALUE(LEFT(F5,FIND("/",F5)-1))-VALUE(LEFT(B5,FIND("/",B5)-1)),"N/A") -> 3
A6: easy-002 | B6: 6/6 | C6: 0 | D6: 10.3 | E6: 0.000682525 | F6: 6/6 | G6: 0 | H6: 10.5 | I6: 0.002557525 | J6: =IFERROR(VALUE(LEFT(F6,FIND("/",F6)-1))-VALUE(LEFT(B6,FIND("/",B6)-1)),"N/A") -> 0
A7: easy-003 | B7: 5/6 | C7: 0 | D7: 9.5 | E7: 0.0001181 | F7: 6/6 | G7: 1 | H7: 10.4 | I7: 0.0043787 | J7: =IFERROR(VALUE(LEFT(F7,FIND("/",F7)-1))-VALUE(LEFT(B7,FIND("/",B7)-1)),"N/A") -> 1
A8: easy-004 | B8: 5/6 | C8: 0 | D8: 10.7 | E8: 0.0001522 | F8: 5/6 | G8: 0 | H8: 10.9 | I8: 0.0020257 | J8: =IFERROR(VALUE(LEFT(F8,FIND("/",F8)-1))-VALUE(LEFT(B8,FIND("/",B8)-1)),"N/A") -> 0
A9: easy-005 | B9: 5/6 | C9: 0 | D9: 10.6 | E9: 0.000161375 | F9: 6/6 | G9: 1 | H9: 11.2 | I9: 0.005915225 | J9: =IFERROR(VALUE(LEFT(F9,FIND("/",F9)-1))-VALUE(LEFT(B9,FIND("/",B9)-1)),"N/A") -> 1
A10: medium-001 | B10: not reached | C10: 5 | D10: 38.2 | E10: 0.00379295 | F10: validator error | G10: 4 | H10: 17.6 | I10: 0.0233867 | J10: =IFERROR(VALUE(LEFT(F10,FIND("/",F10)-1))-VALUE(LEFT(B10,FIND("/",B10)-1)),"N/A") -> N/A
A11: medium-002 | B11: not reached | C11: 5 | D11: 44.4 | E11: 0.00555215 | F11: not reached | G11: 5 | H11: 19.6 | I11: 0.02398565 | J11: =IFERROR(VALUE(LEFT(F11,FIND("/",F11)-1))-VALUE(LEFT(B11,FIND("/",B11)-1)),"N/A") -> N/A
A12: medium-003 | B12: 7/10 | C12: 1 | D12: 10.3 | E12: 0.00063675 | F12: 7/10 | G12: 2 | H12: 10.8 | I12: 0.0082404 | J12: =IFERROR(VALUE(LEFT(F12,FIND("/",F12)-1))-VALUE(LEFT(B12,FIND("/",B12)-1)),"N/A") -> 0
A13: medium-004 | B13: 8/9 | C13: 2 | D13: 33.4 | E13: 0.002280525 | F13: 9/9 | G13: 2 | H13: 13.4 | I13: 0.014839525 | J13: =IFERROR(VALUE(LEFT(F13,FIND("/",F13)-1))-VALUE(LEFT(B13,FIND("/",B13)-1)),"N/A") -> 1
A14: medium-005 | B14: 5/10 | C14: 3 | D14: 19 | E14: 0.002256675 | F14: not reached | G14: 5 | H14: 8.5 | I14: 0.018275025 | J14: =IFERROR(VALUE(LEFT(F14,FIND("/",F14)-1))-VALUE(LEFT(B14,FIND("/",B14)-1)),"N/A") -> N/A
A15: hard-001 | B15: 13/14 | C15: 5 | D15: 54.8 | E15: 0.00500945 | F15: not reached | G15: 5 | H15: 10.1 | I15: 0.03561845 | J15: =IFERROR(VALUE(LEFT(F15,FIND("/",F15)-1))-VALUE(LEFT(B15,FIND("/",B15)-1)),"N/A") -> N/A
A16: hard-002 | B16: not reached | C16: 5 | D16: 54.3 | E16: 0.00553255 | F16: validator error | G16: 0 | H16: 0.5 | I16: 0.00954765 | J16: =IFERROR(VALUE(LEFT(F16,FIND("/",F16)-1))-VALUE(LEFT(B16,FIND("/",B16)-1)),"N/A") -> N/A
... A19: hard-005 | B19: not reached | C19: 5 | D19: 43.5 | E19: 0.008911275 | F19: not reached | G19: 5 | H19: 3.3 | I19: 0.044413325 | J19: =IFERROR(VALUE(LEFT(F19,FIND("/",F19)-1))-VALUE(LEFT(B19,FIND("/",B19)-1)),"N/A") -> N/A
A20: TOTAL | B20: 65/87 (5 not reached) | C20: =SUM(C5:C19) -> 40 | D20: =SUM(D5:D19) -> 425 | E20: =SUM(E5:E19) -> 0.046156075 | F20: 45/49 (5 not reached; 3 technical errors) | G20: =SUM(G5:G19) -> 38 | H20: =SUM(H5:H19) -> 146.1 | I20: =SUM(I5:I19) -> 0.25700632 | J20: =SUM(J5:J19) -> 6

Sheet 5mini - 5.6luna
A1: gpt-5-mini (low) → gpt-5.6-luna (medium)
A4: Task | B4: Off score | C4: Off regens | D4: Off total time (min) | E4: Off cost (USD) | F4: On score | G4: On regens | H4: On total time (min) | I4: On cost (USD) | J4: Effect
A5: easy-001 | B5: 5/6 | C5: 0 | D5: 11.4 | E5: 0.0021295 | F5: 5/6 | G5: 0 | H5: 12.8 | I5: 0.00335845 | J5: =IFERROR(VALUE(LEFT(F5,FIND("/",F5)-1))-VALUE(LEFT(B5,FIND("/",B5)-1)),"N/A") -> 0
A6: easy-002 | B6: 6/6 | C6: 0 | D6: 9.6 | E6: 0.00097675 | F6: 6/6 | G6: 0 | H6: 10.8 | I6: 0.001573 | J6: =IFERROR(VALUE(LEFT(F6,FIND("/",F6)-1))-VALUE(LEFT(B6,FIND("/",B6)-1)),"N/A") -> 0
A7: easy-003 | B7: 6/6 | C7: 0 | D7: 10.5 | E7: 0.000614875 | F7: 6/6 | G7: 0 | H7: 9.9 | I7: 0.000859975 | J7: =IFERROR(VALUE(LEFT(F7,FIND("/",F7)-1))-VALUE(LEFT(B7,FIND("/",B7)-1)),"N/A") -> 0
A8: easy-004 | B8: 4/6 | C8: 0 | D8: 10.8 | E8: 0.000976125 | F8: 5/6 | G8: 1 | H8: 11.1 | I8: 0.004503175 | J8: =IFERROR(VALUE(LEFT(F8,FIND("/",F8)-1))-VALUE(LEFT(B8,FIND("/",B8)-1)),"N/A") -> 1
A9: easy-005 | B9: 4/6 | C9: 0 | D9: 10.6 | E9: 0.002213875 | F9: 6/6 | G9: 1 | H9: 11.5 | I9: 0.009518225 | J9: =IFERROR(VALUE(LEFT(F9,FIND("/",F9)-1))-VALUE(LEFT(B9,FIND("/",B9)-1)),"N/A") -> 2
A10: medium-001 | B10: 10/10 | C10: 0 | D10: 14.7 | E10: 0.00159225 | F10: 9/10 | G10: 0 | H10: 15.1 | I10: 0.0025919 | J10: =IFERROR(VALUE(LEFT(F10,FIND("/",F10)-1))-VALUE(LEFT(B10,FIND("/",B10)-1)),"N/A") -> -1
A11: medium-002 | B11: 9/10 | C11: 0 | D11: 10.2 | E11: 0.00125425 | F11: 9/10 | G11: 0 | H11: 10.8 | I11: 0.001892 | J11: =IFERROR(VALUE(LEFT(F11,FIND("/",F11)-1))-VALUE(LEFT(B11,FIND("/",B11)-1)),"N/A") -> 0
A12: medium-003 | B12: 10/10 | C12: 0 | D12: 11.8 | E12: 0.00161175 | F12: 10/10 | G12: 0 | H12: 12.1 | I12: 0.0026134 | J12: =IFERROR(VALUE(LEFT(F12,FIND("/",F12)-1))-VALUE(LEFT(B12,FIND("/",B12)-1)),"N/A") -> 0
A13: medium-004 | B13: 6/9 | C13: 0 | D13: 11.4 | E13: 0.001621 | F13: 8/9 | G13: 1 | H13: 12.1 | I13: 0.0073583 | J13: =IFERROR(VALUE(LEFT(F13,FIND("/",F13)-1))-VALUE(LEFT(B13,FIND("/",B13)-1)),"N/A") -> 2
A14: medium-005 | B14: 9/10 | C14: 0 | D14: 11.9 | E14: 0.001886625 | F14: 10/10 | G14: 1 | H14: 13.5 | I14: 0.007508825 | J14: =IFERROR(VALUE(LEFT(F14,FIND("/",F14)-1))-VALUE(LEFT(B14,FIND("/",B14)-1)),"N/A") -> 1
A15: hard-001 | B15: 10/14 | C15: 0 | D15: 13.9 | E15: 0.002246375 | F15: 13/14 | G15: 1 | H15: 15.8 | I15: 0.009493975 | J15: =IFERROR(VALUE(LEFT(F15,FIND("/",F15)-1))-VALUE(LEFT(B15,FIND("/",B15)-1)),"N/A") -> 3
A16: hard-002 | B16: 11/14 | C16: 0 | D16: 13.4 | E16: 0.002767125 | F16: 11/14 | G16: 0 | H16: 13.7 | I16: 0.004690625 | J16: =IFERROR(VALUE(LEFT(F16,FIND("/",F16)-1))-VALUE(LEFT(B16,FIND("/",B16)-1)),"N/A") -> 0
... A19: hard-005 | B19: not reached | C19: 5 | D19: 43.1 | E19: 0.048179525 | F19: 11/14 | G19: 5 | H19: 39.3 | I19: 0.068235225 | J19: =IFERROR(VALUE(LEFT(F19,FIND("/",F19)-1))-VALUE(LEFT(B19,FIND("/",B19)-1)),"N/A") -> N/A
A20: TOTAL | B20: 109/135 (1 not reached) | C20: =SUM(C5:C19) -> 6 | D20: =SUM(D5:D19) -> 220.1 | E20: =SUM(E5:E19) -> 0.08389765 | F20: 128/149 | G20: =SUM(G5:G19) -> 13 | H20: =SUM(H5:H19) -> 230.3 | I20: =SUM(I5:I19) -> 0.1735658 | J20: =SUM(J5:J19) -> 8

Sheet 5.4mini - 5.6luna
A1: gpt-5.4-mini (low) → gpt-5.6-luna (medium)
A4: Task | B4: Off score | C4: Off regens | D4: Off total time (min) | E4: Off cost (USD) | F4: On score | G4: On regens | H4: On total time (min) | I4: On cost (USD) | J4: Effect
A5: easy-001 | B5: 6/6 | C5: 0 | D5: 11.1 | E5: 0.0028005 | F5: 6/6 | G5: 0 | H5: 11.3 | I5: 0.003361 | J5: =IFERROR(VALUE(LEFT(F5,FIND("/",F5)-1))-VALUE(LEFT(B5,FIND("/",B5)-1)),"N/A") -> 0
A6: easy-002 | B6: 6/6 | C6: 0 | D6: 9.7 | E6: 0.00155025 | F6: 6/6 | G6: 0 | H6: 10 | I6: 0.00205885 | J6: =IFERROR(VALUE(LEFT(F6,FIND("/",F6)-1))-VALUE(LEFT(B6,FIND("/",B6)-1)),"N/A") -> 0
A7: easy-003 | B7: 6/6 | C7: 0 | D7: 9.7 | E7: 0.001122 | F7: 6/6 | G7: 0 | H7: 10.3 | I7: 0.0013832 | J7: =IFERROR(VALUE(LEFT(F7,FIND("/",F7)-1))-VALUE(LEFT(B7,FIND("/",B7)-1)),"N/A") -> 0
A8: easy-004 | B8: 6/6 | C8: 0 | D8: 11.1 | E8: 0.001633125 | F8: 6/6 | G8: 0 | H8: 10.9 | I8: 0.002185175 | J8: =IFERROR(VALUE(LEFT(F8,FIND("/",F8)-1))-VALUE(LEFT(B8,FIND("/",B8)-1)),"N/A") -> 0
A9: easy-005 | B9: 6/6 | C9: 0 | D9: 10.6 | E9: 0.002227125 | F9: 6/6 | G9: 0 | H9: 10.5 | I9: 0.002881725 | J9: =IFERROR(VALUE(LEFT(F9,FIND("/",F9)-1))-VALUE(LEFT(B9,FIND("/",B9)-1)),"N/A") -> 0
A10: medium-001 | B10: 10/10 | C10: 1 | D10: 22.6 | E10: 0.009137625 | F10: 10/10 | G10: 1 | H10: 22.5 | I10: 0.011451975 | J10: =IFERROR(VALUE(LEFT(F10,FIND("/",F10)-1))-VALUE(LEFT(B10,FIND("/",B10)-1)),"N/A") -> 0
A11: medium-002 | B11: 10/10 | C11: 0 | D11: 10.4 | E11: 0.002128875 | F11: 10/10 | G11: 0 | H11: 10.5 | I11: 0.003022125 | J11: =IFERROR(VALUE(LEFT(F11,FIND("/",F11)-1))-VALUE(LEFT(B11,FIND("/",B11)-1)),"N/A") -> 0
A12: medium-003 | B12: 10/10 | C12: 0 | D12: 11.8 | E12: 0.003047625 | F12: 10/10 | G12: 0 | H12: 11.9 | I12: 0.004050275 | J12: =IFERROR(VALUE(LEFT(F12,FIND("/",F12)-1))-VALUE(LEFT(B12,FIND("/",B12)-1)),"N/A") -> 0
A13: medium-004 | B13: 7/9 | C13: 0 | D13: 12.1 | E13: 0.003484875 | F13: 9/9 | G13: 1 | H13: 12.5 | I13: 0.012066125 | J13: =IFERROR(VALUE(LEFT(F13,FIND("/",F13)-1))-VALUE(LEFT(B13,FIND("/",B13)-1)),"N/A") -> 2
A14: medium-005 | B14: 10/10 | C14: 0 | D14: 12.9 | E14: 0.003252375 | F14: 10/10 | G14: 0 | H14: 13 | I14: 0.004290925 | J14: =IFERROR(VALUE(LEFT(F14,FIND("/",F14)-1))-VALUE(LEFT(B14,FIND("/",B14)-1)),"N/A") -> 0
A15: hard-001 | B15: 13/14 | C15: 0 | D15: 16 | E15: 0.00401775 | F15: 14/14 | G15: 1 | H15: 16.8 | I15: 0.01589 | J15: =IFERROR(VALUE(LEFT(F15,FIND("/",F15)-1))-VALUE(LEFT(B15,FIND("/",B15)-1)),"N/A") -> 1
A16: hard-002 | B16: 12/14 | C16: 0 | D16: 13.3 | E16: 0.006034125 | F16: 14/14 | G16: 0 | H16: 14.2 | I16: 0.008568725 | J16: =IFERROR(VALUE(LEFT(F16,FIND("/",F16)-1))-VALUE(LEFT(B16,FIND("/",B16)-1)),"N/A") -> 2
... A19: hard-005 | B19: 9/14 | C19: 0 | D19: 13.7 | E19: 0.008788875 | F19: 12/14 | G19: 1 | H19: 16.9 | I19: 0.029094375 | J19: =IFERROR(VALUE(LEFT(F19,FIND("/",F19)-1))-VALUE(LEFT(B19,FIND("/",B19)-1)),"N/A") -> 3
A20: TOTAL | B20: 130/149 | C20: =SUM(C5:C19) -> 1 | D20: =SUM(D5:D19) -> 191.8 | E20: =SUM(E5:E19) -> 0.063906375 | F20: 143/149 | G20: =SUM(G5:G19) -> 6 | H20: =SUM(H5:H19) -> 201.8 | I20: =SUM(I5:I19) -> 0.14902667 | J20: =SUM(J5:J19) -> 13

Sheet Gemma4 - 5.4mini med
A1: google/gemma-4-26b-a4b-it (medium) → gpt-5.4-mini (medium)
A4: Task | B4: Off score | C4: Off regens | D4: Off total time (min) | E4: Off cost (USD) | F4: On score | G4: On regens | H4: On total time (min) | I4: On cost (USD) | J4: Effect
A5: easy-001 | B5: 5/6 | C5: 0 | D5: 13.8 | E5: 0.000882655 | F5: 5/6 | G5: 0 | H5: 14.1 | I5: 0.007037155 | J5: =IFERROR(VALUE(LEFT(F5,FIND("/",F5)-1))-VALUE(LEFT(B5,FIND("/",B5)-1)),"N/A") -> 0
A6: easy-002 | B6: 6/6 | C6: 0 | D6: 11.4 | E6: 0.00097348 | F6: 6/6 | G6: 0 | H6: 11.4 | I6: 0.00420523 | J6: =IFERROR(VALUE(LEFT(F6,FIND("/",F6)-1))-VALUE(LEFT(B6,FIND("/",B6)-1)),"N/A") -> 0
A7: easy-003 | B7: 6/6 | C7: 0 | D7: 10.3 | E7: 0.000318215 | F7: 6/6 | G7: 0 | H7: 10.5 | I7: 0.002839715 | J7: =IFERROR(VALUE(LEFT(F7,FIND("/",F7)-1))-VALUE(LEFT(B7,FIND("/",B7)-1)),"N/A") -> 0
A8: easy-004 | B8: 5/6 | C8: 0 | D8: 12.1 | E8: 0.000846085 | F8: 5/6 | G8: 0 | H8: 12.4 | I8: 0.004740835 | J8: =IFERROR(VALUE(LEFT(F8,FIND("/",F8)-1))-VALUE(LEFT(B8,FIND("/",B8)-1)),"N/A") -> 0
A9: easy-005 | B9: 6/6 | C9: 0 | D9: 12.5 | E9: 0.00083321 | F9: 6/6 | G9: 0 | H9: 12 | I9: 0.00560171 | J9: =IFERROR(VALUE(LEFT(F9,FIND("/",F9)-1))-VALUE(LEFT(B9,FIND("/",B9)-1)),"N/A") -> 0
A10: medium-001 | B10: 8/10 | C10: 0 | D10: 14.2 | E10: 0.001207 | F10: 9/10 | G10: 1 | H10: 18 | I10: 0.02930412 | J10: =IFERROR(VALUE(LEFT(F10,FIND("/",F10)-1))-VALUE(LEFT(B10,FIND("/",B10)-1)),"N/A") -> 1
A11: medium-002 | B11: 9/10 | C11: 0 | D11: 12.2 | E11: 0.000783535 | F11: 10/10 | G11: 2 | H11: 18.2 | I11: 0.023828835 | J11: =IFERROR(VALUE(LEFT(F11,FIND("/",F11)-1))-VALUE(LEFT(B11,FIND("/",B11)-1)),"N/A") -> 1
A12: medium-003 | B12: 9/10 | C12: 0 | D12: 13.7 | E12: 0.000874565 | F12: 9/10 | G12: 0 | H12: 14.1 | I12: 0.011989565 | J12: =IFERROR(VALUE(LEFT(F12,FIND("/",F12)-1))-VALUE(LEFT(B12,FIND("/",B12)-1)),"N/A") -> 0
A13: medium-004 | B13: 9/9 | C13: 0 | D13: 14 | E13: 0.001198255 | F13: 9/9 | G13: 0 | H13: 14.1 | I13: 0.011150755 | J13: =IFERROR(VALUE(LEFT(F13,FIND("/",F13)-1))-VALUE(LEFT(B13,FIND("/",B13)-1)),"N/A") -> 0
A14: medium-005 | B14: 10/10 | C14: 0 | D14: 14.6 | E14: 0.001173595 | F14: 10/10 | G14: 0 | H14: 15.1 | I14: 0.010925845 | J14: =IFERROR(VALUE(LEFT(F14,FIND("/",F14)-1))-VALUE(LEFT(B14,FIND("/",B14)-1)),"N/A") -> 0
A15: hard-001 | B15: 13/14 | C15: 0 | D15: 15.1 | E15: 0.00119935 | F15: 14/14 | G15: 1 | H15: 21.9 | I15: 0.0249202 | J15: =IFERROR(VALUE(LEFT(F15,FIND("/",F15)-1))-VALUE(LEFT(B15,FIND("/",B15)-1)),"N/A") -> 1
A16: hard-002 | B16: 12/14 | C16: 0 | D16: 16.3 | E16: 0.001343965 | F16: 12/14 | G16: 0 | H16: 17.9 | I16: 0.046859965 | J16: =IFERROR(VALUE(LEFT(F16,FIND("/",F16)-1))-VALUE(LEFT(B16,FIND("/",B16)-1)),"N/A") -> 0
... A19: hard-005 | B19: 9/14 | C19: 1 | D19: 32.3 | E19: 0.00535596 | F19: 10/14 | G19: 1 | H19: 26.8 | I19: 0.08668765 | J19: =IFERROR(VALUE(LEFT(F19,FIND("/",F19)-1))-VALUE(LEFT(B19,FIND("/",B19)-1)),"N/A") -> 1
A20: TOTAL | B20: 128/149 | C20: =SUM(C5:C19) -> 1 | D20: =SUM(D5:D19) -> 233.2 | E20: =SUM(E5:E19) -> 0.02003568 | F20: 133/149 | G20: =SUM(G5:G19) -> 6 | H20: =SUM(H5:H19) -> 255.7 | I20: =SUM(I5:I19) -> 0.38753151 | J20: =SUM(J5:J19) -> 5

Sheet Qwen3.5 9B - 5.4mini med
A1: qwen/qwen3.5-9b (medium) → gpt-5.4-mini (medium)
A4: Task | B4: Off score | C4: Off regens | D4: Off total time (min) | E4: Off cost (USD) | F4: On score | G4: On regens | H4: On total time (min) | I4: On cost (USD) | J4: Effect
A5: easy-001 | B5: 3/6 | C5: 3 | D5: 32.8 | E5: 0.00185695 | F5: 4/6 | G5: 2 | H5: 12.6 | I5: 0.0272287 | J5: =IFERROR(VALUE(LEFT(F5,FIND("/",F5)-1))-VALUE(LEFT(B5,FIND("/",B5)-1)),"N/A") -> 1
A6: easy-002 | B6: 6/6 | C6: 0 | D6: 10.3 | E6: 0.000682525 | F6: 6/6 | G6: 0 | H6: 11.4 | I6: 0.006004525 | J6: =IFERROR(VALUE(LEFT(F6,FIND("/",F6)-1))-VALUE(LEFT(B6,FIND("/",B6)-1)),"N/A") -> 0
A7: easy-003 | B7: 5/6 | C7: 0 | D7: 9.5 | E7: 0.0001181 | F7: 6/6 | G7: 1 | H7: 10.1 | I7: 0.00618775 | J7: =IFERROR(VALUE(LEFT(F7,FIND("/",F7)-1))-VALUE(LEFT(B7,FIND("/",B7)-1)),"N/A") -> 1
A8: easy-004 | B8: 5/6 | C8: 0 | D8: 10.7 | E8: 0.0001522 | F8: 5/6 | G8: 0 | H8: 10.9 | I8: 0.0043657 | J8: =IFERROR(VALUE(LEFT(F8,FIND("/",F8)-1))-VALUE(LEFT(B8,FIND("/",B8)-1)),"N/A") -> 0
A9: easy-005 | B9: 5/6 | C9: 0 | D9: 10.6 | E9: 0.000161375 | F9: 6/6 | G9: 2 | H9: 11.3 | I9: 0.020967725 | J9: =IFERROR(VALUE(LEFT(F9,FIND("/",F9)-1))-VALUE(LEFT(B9,FIND("/",B9)-1)),"N/A") -> 1
A10: medium-001 | B10: not reached | C10: 5 | D10: 38.2 | E10: 0.00379295 | F10: not reached | G10: 5 | H10: 12.6 | I10: 0.080024 | J10: =IFERROR(VALUE(LEFT(F10,FIND("/",F10)-1))-VALUE(LEFT(B10,FIND("/",B10)-1)),"N/A") -> N/A
A11: medium-002 | B11: not reached | C11: 5 | D11: 44.4 | E11: 0.00555215 | F11: not reached | G11: 5 | H11: 17.8 | I11: 0.0690423 | J11: =IFERROR(VALUE(LEFT(F11,FIND("/",F11)-1))-VALUE(LEFT(B11,FIND("/",B11)-1)),"N/A") -> N/A
A12: medium-003 | B12: 7/10 | C12: 1 | D12: 10.3 | E12: 0.00063675 | F12: 7/10 | G12: 2 | H12: 11.9 | I12: 0.03941205 | J12: =IFERROR(VALUE(LEFT(F12,FIND("/",F12)-1))-VALUE(LEFT(B12,FIND("/",B12)-1)),"N/A") -> 0
A13: medium-004 | B13: 8/9 | C13: 2 | D13: 33.4 | E13: 0.002280525 | F13: 9/9 | G13: 2 | H13: 13 | I13: 0.031382325 | J13: =IFERROR(VALUE(LEFT(F13,FIND("/",F13)-1))-VALUE(LEFT(B13,FIND("/",B13)-1)),"N/A") -> 1
A14: medium-005 | B14: 5/10 | C14: 3 | D14: 19 | E14: 0.002256675 | F14: 9/10 | G14: 5 | H14: 15.7 | I14: 0.043436525 | J14: =IFERROR(VALUE(LEFT(F14,FIND("/",F14)-1))-VALUE(LEFT(B14,FIND("/",B14)-1)),"N/A") -> 4
A15: hard-001 | B15: 13/14 | C15: 5 | D15: 54.8 | E15: 0.00500945 | F15: provider error | G15: 2 | H15: 10.9 | I15: 0.02836955 | J15: =IFERROR(VALUE(LEFT(F15,FIND("/",F15)-1))-VALUE(LEFT(B15,FIND("/",B15)-1)),"N/A") -> N/A
A16: hard-002 | B16: not reached | C16: 5 | D16: 54.3 | E16: 0.00553255 | F16: not reached | G16: 5 | H16: 6.9 | I16: 0.14365555 | J16: =IFERROR(VALUE(LEFT(F16,FIND("/",F16)-1))-VALUE(LEFT(B16,FIND("/",B16)-1)),"N/A") -> N/A
... A19: hard-005 | B19: not reached | C19: 5 | D19: 43.5 | E19: 0.008911275 | F19: not reached | G19: 5 | H19: 6 | I19: 0.11092152 | J19: =IFERROR(VALUE(LEFT(F19,FIND("/",F19)-1))-VALUE(LEFT(B19,FIND("/",B19)-1)),"N/A") -> N/A
A20: TOTAL | B20: 65/87 (5 not reached) | C20: =SUM(C5:C19) -> 40 | D20: =SUM(D5:D19) -> 425 | E20: =SUM(E5:E19) -> 0.046156075 | F20: 52/59 (6 not reached; 1 technical errors) | G20: =SUM(G5:G19) -> 46 | H20: =SUM(H5:H19) -> 166.2 | I20: =SUM(I5:I19) -> 0.92720928 | J20: =SUM(J5:J19) -> 8

Sheet DeepSeek V4 - DeepSeek
A1: deepseek/deepseek-v4-flash-0731 (high) → deepseek/deepseek-v4-flash-0731 (high)
A4: Task | B4: Off score | C4: Off regens | D4: Off total time (min) | E4: Off cost (USD) | F4: On score | G4: On regens | H4: On total time (min) | I4: On cost (USD) | J4: Effect
A5: easy-001 | B5: 5/6 | C5: 0 | D5: 11.7 | E5: 0.00051356 | F5: 5/6 | G5: 0 | H5: 36.8 | I5: 0.01217234 | J5: =IFERROR(VALUE(LEFT(F5,FIND("/",F5)-1))-VALUE(LEFT(B5,FIND("/",B5)-1)),"N/A") -> 0
A6: easy-002 | B6: 6/6 | C6: 0 | D6: 9.9 | E6: 0.00015862 | F6: 6/6 | G6: 0 | H6: 18.4 | I6: 0.0061589 | J6: =IFERROR(VALUE(LEFT(F6,FIND("/",F6)-1))-VALUE(LEFT(B6,FIND("/",B6)-1)),"N/A") -> 0
A7: easy-003 | B7: 6/6 | C7: 0 | D7: 9.8 | E7: 6.4264e-05 | F7: 6/6 | G7: 0 | H7: 10.5 | I7: 0.000259004 | J7: =IFERROR(VALUE(LEFT(F7,FIND("/",F7)-1))-VALUE(LEFT(B7,FIND("/",B7)-1)),"N/A") -> 0
A8: easy-004 | B8: 6/6 | C8: 0 | D8: 12.7 | E8: 0.000552314 | F8: 6/6 | G8: 0 | H8: 13.6 | I8: 0.000958594 | J8: =IFERROR(VALUE(LEFT(F8,FIND("/",F8)-1))-VALUE(LEFT(B8,FIND("/",B8)-1)),"N/A") -> 0
A9: easy-005 | B9: 6/6 | C9: 0 | D9: 11 | E9: 0.000335244 | F9: 6/6 | G9: 0 | H9: 19.6 | I9: 0.005683244 | J9: =IFERROR(VALUE(LEFT(F9,FIND("/",F9)-1))-VALUE(LEFT(B9,FIND("/",B9)-1)),"N/A") -> 0
A10: medium-001 | B10: 10/10 | C10: 0 | D10: 22 | E10: 0.001868104 | F10: 10/10 | G10: 0 | H10: 50.3 | I10: 0.011964264 | J10: =IFERROR(VALUE(LEFT(F10,FIND("/",F10)-1))-VALUE(LEFT(B10,FIND("/",B10)-1)),"N/A") -> 0
A11: medium-002 | B11: 10/10 | C11: 0 | D11: 19.7 | E11: 0.002315364 | F11: 10/10 | G11: 0 | H11: 27.1 | I11: 0.005918304 | J11: =IFERROR(VALUE(LEFT(F11,FIND("/",F11)-1))-VALUE(LEFT(B11,FIND("/",B11)-1)),"N/A") -> 0
A12: medium-003 | B12: 10/10 | C12: 0 | D12: 21.5 | E12: 0.00212563 | F12: 10/10 | G12: 0 | H12: 21.6 | I12: 0.00234769 | J12: =IFERROR(VALUE(LEFT(F12,FIND("/",F12)-1))-VALUE(LEFT(B12,FIND("/",B12)-1)),"N/A") -> 0
A13: medium-004 | B13: 9/9 | C13: 0 | D13: 20.7 | E13: 0.002262744 | F13: 9/9 | G13: 0 | H13: 22.5 | I13: 0.003812984 | J13: =IFERROR(VALUE(LEFT(F13,FIND("/",F13)-1))-VALUE(LEFT(B13,FIND("/",B13)-1)),"N/A") -> 0
A14: medium-005 | B14: 10/10 | C14: 0 | D14: 29.6 | E14: 0.0025374 | F14: 10/10 | G14: 0 | H14: 42.1 | I14: 0.01100582 | J14: =IFERROR(VALUE(LEFT(F14,FIND("/",F14)-1))-VALUE(LEFT(B14,FIND("/",B14)-1)),"N/A") -> 0
A15: hard-001 | B15: 14/14 | C15: 0 | D15: 25.3 | E15: 0.0017454 | F15: 14/14 | G15: 0 | H15: 30.4 | I15: 0.00425942 | J15: =IFERROR(VALUE(LEFT(F15,FIND("/",F15)-1))-VALUE(LEFT(B15,FIND("/",B15)-1)),"N/A") -> 0
A16: hard-002 | B16: 11/14 | C16: 0 | D16: 17.9 | E16: 0.001397404 | F16: validator error | G16: 0 | H16: 50.7 | I16: 0.030943164 | J16: =IFERROR(VALUE(LEFT(F16,FIND("/",F16)-1))-VALUE(LEFT(B16,FIND("/",B16)-1)),"N/A") -> N/A
... A19: hard-005 | B19: 12/14 | C19: 0 | D19: 24.1 | E19: 0.00307008 | F19: 12/14 | G19: 0 | H19: 43.6 | I19: 0.01143472 | J19: =IFERROR(VALUE(LEFT(F19,FIND("/",F19)-1))-VALUE(LEFT(B19,FIND("/",B19)-1)),"N/A") -> 0
A20: TOTAL | B20: 134/149 | C20: =SUM(C5:C19) -> 1 | D20: =SUM(D5:D19) -> 289.8 | E20: =SUM(E5:E19) -> 0.024598118 | F20: 116/121 (2 technical errors) | G20: =SUM(G5:G19) -> 3 | H20: =SUM(H5:H19) -> 579.2 | I20: =SUM(I5:I19) -> 0.17393046 | J20: =SUM(J5:J19) -> 2

Sheet 5mini - 5.4mini med
A1: gpt-5-mini (low) → gpt-5.4-mini (medium)
A4: Task | B4: Off score | C4: Off regens | D4: Off total time (min) | E4: Off cost (USD) | F4: On score | G4: On regens | H4: On total time (min) | I4: On cost (USD) | J4: Effect
A5: easy-001 | B5: 5/6 | C5: 0 | D5: 11.4 | E5: 0.0021295 | F5: 5/6 | G5: 0 | H5: 11.8 | I5: 0.01468 | J5: =IFERROR(VALUE(LEFT(F5,FIND("/",F5)-1))-VALUE(LEFT(B5,FIND("/",B5)-1)),"N/A") -> 0
A6: easy-002 | B6: 6/6 | C6: 0 | D6: 9.6 | E6: 0.00097675 | F6: 6/6 | G6: 0 | H6: 9.9 | I6: 0.006691 | J6: =IFERROR(VALUE(LEFT(F6,FIND("/",F6)-1))-VALUE(LEFT(B6,FIND("/",B6)-1)),"N/A") -> 0
A7: easy-003 | B7: 6/6 | C7: 0 | D7: 10.5 | E7: 0.000614875 | F7: 6/6 | G7: 0 | H7: 10.3 | I7: 0.002956375 | J7: =IFERROR(VALUE(LEFT(F7,FIND("/",F7)-1))-VALUE(LEFT(B7,FIND("/",B7)-1)),"N/A") -> 0
A8: easy-004 | B8: 4/6 | C8: 0 | D8: 10.8 | E8: 0.000976125 | F8: 5/6 | G8: 1 | H8: 11.2 | I8: 0.019632125 | J8: =IFERROR(VALUE(LEFT(F8,FIND("/",F8)-1))-VALUE(LEFT(B8,FIND("/",B8)-1)),"N/A") -> 1
A9: easy-005 | B9: 4/6 | C9: 0 | D9: 10.6 | E9: 0.002213875 | F9: 6/6 | G9: 1 | H9: 11.3 | I9: 0.025785375 | J9: =IFERROR(VALUE(LEFT(F9,FIND("/",F9)-1))-VALUE(LEFT(B9,FIND("/",B9)-1)),"N/A") -> 2
A10: medium-001 | B10: 10/10 | C10: 0 | D10: 14.7 | E10: 0.00159225 | F10: 9/10 | G10: 0 | H10: 15.9 | I10: 0.0189 | J10: =IFERROR(VALUE(LEFT(F10,FIND("/",F10)-1))-VALUE(LEFT(B10,FIND("/",B10)-1)),"N/A") -> -1
A11: medium-002 | B11: 9/10 | C11: 0 | D11: 10.2 | E11: 0.00125425 | F11: 10/10 | G11: 1 | H11: 11.7 | I11: 0.03308365 | J11: =IFERROR(VALUE(LEFT(F11,FIND("/",F11)-1))-VALUE(LEFT(B11,FIND("/",B11)-1)),"N/A") -> 1
A12: medium-003 | B12: 10/10 | C12: 0 | D12: 11.8 | E12: 0.00161175 | F12: 10/10 | G12: 0 | H12: 12.1 | I12: 0.0157485 | J12: =IFERROR(VALUE(LEFT(F12,FIND("/",F12)-1))-VALUE(LEFT(B12,FIND("/",B12)-1)),"N/A") -> 0
A13: medium-004 | B13: 6/9 | C13: 0 | D13: 11.4 | E13: 0.001621 | F13: 9/9 | G13: 1 | H13: 12.8 | I13: 0.0260739 | J13: =IFERROR(VALUE(LEFT(F13,FIND("/",F13)-1))-VALUE(LEFT(B13,FIND("/",B13)-1)),"N/A") -> 3
A14: medium-005 | B14: 9/10 | C14: 0 | D14: 11.9 | E14: 0.001886625 | F14: 10/10 | G14: 1 | H14: 13.7 | I14: 0.027699775 | J14: =IFERROR(VALUE(LEFT(F14,FIND("/",F14)-1))-VALUE(LEFT(B14,FIND("/",B14)-1)),"N/A") -> 1
A15: hard-001 | B15: 10/14 | C15: 0 | D15: 13.9 | E15: 0.002246375 | F15: 13/14 | G15: 1 | H15: 16.2 | I15: 0.032750775 | J15: =IFERROR(VALUE(LEFT(F15,FIND("/",F15)-1))-VALUE(LEFT(B15,FIND("/",B15)-1)),"N/A") -> 3
A16: hard-002 | B16: 11/14 | C16: 0 | D16: 13.4 | E16: 0.002767125 | F16: 11/14 | G16: 0 | H16: 13.6 | I16: 0.015032625 | J16: =IFERROR(VALUE(LEFT(F16,FIND("/",F16)-1))-VALUE(LEFT(B16,FIND("/",B16)-1)),"N/A") -> 0
... A19: hard-005 | B19: not reached | C19: 5 | D19: 43.1 | E19: 0.048179525 | F19: not reached | G19: 5 | H19: 22.8 | I19: 0.27969637 | J19: =IFERROR(VALUE(LEFT(F19,FIND("/",F19)-1))-VALUE(LEFT(B19,FIND("/",B19)-1)),"N/A") -> N/A
A20: TOTAL | B20: 109/135 (1 not reached) | C20: =SUM(C5:C19) -> 6 | D20: =SUM(D5:D19) -> 220.1 | E20: =SUM(E5:E19) -> 0.08389765 | F20: 111/121 (2 not reached) | G20: =SUM(G5:G19) -> 16 | H20: =SUM(H5:H19) -> 220.2 | I20: =SUM(I5:I19) -> 0.83773265 | J20: =SUM(J5:J19) -> 10

Sheet 5mini - 5.6sol
A1: gpt-5-mini (low) → gpt-5.6-sol (medium)
A4: Task | B4: Off score | C4: Off regens | D4: Off total time (min) | E4: Off cost (USD) | F4: On score | G4: On regens | H4: On total time (min) | I4: On cost (USD) | J4: Effect
A5: easy-001 | B5: 5/6 | C5: 0 | D5: 11.4 | E5: 0.0021295 | F5: 5/6 | G5: 0 | H5: 11.8 | I5: 0.008923 | J5: =IFERROR(VALUE(LEFT(F5,FIND("/",F5)-1))-VALUE(LEFT(B5,FIND("/",B5)-1)),"N/A") -> 0
A6: easy-002 | B6: 6/6 | C6: 0 | D6: 9.6 | E6: 0.00097675 | F6: 6/6 | G6: 0 | H6: 10.2 | I6: 0.00706725 | J6: =IFERROR(VALUE(LEFT(F6,FIND("/",F6)-1))-VALUE(LEFT(B6,FIND("/",B6)-1)),"N/A") -> 0
A7: easy-003 | B7: 6/6 | C7: 0 | D7: 10.5 | E7: 0.000614875 | F7: 6/6 | G7: 0 | H7: 9.9 | I7: 0.002207875 | J7: =IFERROR(VALUE(LEFT(F7,FIND("/",F7)-1))-VALUE(LEFT(B7,FIND("/",B7)-1)),"N/A") -> 0
A8: easy-004 | B8: 4/6 | C8: 0 | D8: 10.8 | E8: 0.000976125 | F8: 5/6 | G8: 1 | H8: 11.3 | I8: 0.013652125 | J8: =IFERROR(VALUE(LEFT(F8,FIND("/",F8)-1))-VALUE(LEFT(B8,FIND("/",B8)-1)),"N/A") -> 1
A9: easy-005 | B9: 4/6 | C9: 0 | D9: 10.6 | E9: 0.002213875 | F9: 6/6 | G9: 1 | H9: 11.4 | I9: 0.024931625 | J9: =IFERROR(VALUE(LEFT(F9,FIND("/",F9)-1))-VALUE(LEFT(B9,FIND("/",B9)-1)),"N/A") -> 2
A10: medium-001 | B10: 10/10 | C10: 0 | D10: 14.7 | E10: 0.00159225 | F10: 9/10 | G10: 0 | H10: 14.9 | I10: 0.00770275 | J10: =IFERROR(VALUE(LEFT(F10,FIND("/",F10)-1))-VALUE(LEFT(B10,FIND("/",B10)-1)),"N/A") -> -1
A11: medium-002 | B11: 9/10 | C11: 0 | D11: 10.2 | E11: 0.00125425 | F11: 10/10 | G11: 1 | H11: 11 | I11: 0.0222135 | J11: =IFERROR(VALUE(LEFT(F11,FIND("/",F11)-1))-VALUE(LEFT(B11,FIND("/",B11)-1)),"N/A") -> 1
A12: medium-003 | B12: 10/10 | C12: 0 | D12: 11.8 | E12: 0.00161175 | F12: 10/10 | G12: 0 | H12: 12.1 | I12: 0.01035225 | J12: =IFERROR(VALUE(LEFT(F12,FIND("/",F12)-1))-VALUE(LEFT(B12,FIND("/",B12)-1)),"N/A") -> 0
A13: medium-004 | B13: 6/9 | C13: 0 | D13: 11.4 | E13: 0.001621 | F13: 9/9 | G13: 1 | H13: 12.6 | I13: 0.02120325 | J13: =IFERROR(VALUE(LEFT(F13,FIND("/",F13)-1))-VALUE(LEFT(B13,FIND("/",B13)-1)),"N/A") -> 3
A14: medium-005 | B14: 9/10 | C14: 0 | D14: 11.9 | E14: 0.001886625 | F14: 10/10 | G14: 1 | H14: 13.3 | I14: 0.018592125 | J14: =IFERROR(VALUE(LEFT(F14,FIND("/",F14)-1))-VALUE(LEFT(B14,FIND("/",B14)-1)),"N/A") -> 1
A15: hard-001 | B15: 10/14 | C15: 0 | D15: 13.9 | E15: 0.002246375 | F15: 13/14 | G15: 1 | H15: 16.4 | I15: 0.033248125 | J15: =IFERROR(VALUE(LEFT(F15,FIND("/",F15)-1))-VALUE(LEFT(B15,FIND("/",B15)-1)),"N/A") -> 3
A16: hard-002 | B16: 11/14 | C16: 0 | D16: 13.4 | E16: 0.002767125 | F16: 11/14 | G16: 0 | H16: 13.9 | I16: 0.017940125 | J16: =IFERROR(VALUE(LEFT(F16,FIND("/",F16)-1))-VALUE(LEFT(B16,FIND("/",B16)-1)),"N/A") -> 0
... A19: hard-005 | B19: not reached | C19: 5 | D19: 43.1 | E19: 0.048179525 | F19: not reached | G19: 5 | H19: 30.5 | I19: 0.21935902 | J19: =IFERROR(VALUE(LEFT(F19,FIND("/",F19)-1))-VALUE(LEFT(B19,FIND("/",B19)-1)),"N/A") -> N/A
A20: TOTAL | B20: 109/135 (1 not reached) | C20: =SUM(C5:C19) -> 6 | D20: =SUM(D5:D19) -> 220.1 | E20: =SUM(E5:E19) -> 0.08389765 | F20: 119/135 (1 not reached) | G20: =SUM(G5:G19) -> 12 | H20: =SUM(H5:H19) -> 218.3 | I20: =SUM(I5:I19) -> 0.47612815 | J20: =SUM(J5:J19) -> 10

Sheet 5mini - DeepSeek V4
A1: gpt-5-mini (low) → deepseek/deepseek-v4-flash-0731 (high)
A4: Task | B4: Off score | C4: Off regens | D4: Off total time (min) | E4: Off cost (USD) | F4: On score | G4: On regens | H4: On total time (min) | I4: On cost (USD) | J4: Effect
A5: easy-001 | B5: 5/6 | C5: 0 | D5: 11.4 | E5: 0.0021295 | F5: 5/6 | G5: 0 | H5: 13.5 | I5: 0.00301708 | J5: =IFERROR(VALUE(LEFT(F5,FIND("/",F5)-1))-VALUE(LEFT(B5,FIND("/",B5)-1)),"N/A") -> 0
A6: easy-002 | B6: 6/6 | C6: 0 | D6: 9.6 | E6: 0.00097675 | F6: 6/6 | G6: 0 | H6: 48.3 | I6: 0.02718432 | J6: =IFERROR(VALUE(LEFT(F6,FIND("/",F6)-1))-VALUE(LEFT(B6,FIND("/",B6)-1)),"N/A") -> 0
A7: easy-003 | B7: 6/6 | C7: 0 | D7: 10.5 | E7: 0.000614875 | F7: 6/6 | G7: 0 | H7: 10.1 | I7: 0.000857715 | J7: =IFERROR(VALUE(LEFT(F7,FIND("/",F7)-1))-VALUE(LEFT(B7,FIND("/",B7)-1)),"N/A") -> 0
A8: easy-004 | B8: 4/6 | C8: 0 | D8: 10.8 | E8: 0.000976125 | F8: 6/6 | G8: 1 | H8: 12.3 | I8: 0.003790335 | J8: =IFERROR(VALUE(LEFT(F8,FIND("/",F8)-1))-VALUE(LEFT(B8,FIND("/",B8)-1)),"N/A") -> 2
A9: easy-005 | B9: 4/6 | C9: 0 | D9: 10.6 | E9: 0.002213875 | F9: 6/6 | G9: 1 | H9: 39.2 | I9: 0.017787405 | J9: =IFERROR(VALUE(LEFT(F9,FIND("/",F9)-1))-VALUE(LEFT(B9,FIND("/",B9)-1)),"N/A") -> 2
A10: medium-001 | B10: 10/10 | C10: 0 | D10: 14.7 | E10: 0.00159225 | F10: 9/10 | G10: 0 | H10: 62.8 | I10: 0.02595509 | J10: =IFERROR(VALUE(LEFT(F10,FIND("/",F10)-1))-VALUE(LEFT(B10,FIND("/",B10)-1)),"N/A") -> -1
A11: medium-002 | B11: 9/10 | C11: 0 | D11: 10.2 | E11: 0.00125425 | F11: 10/10 | G11: 1 | H11: 53.3 | I11: 0.02200221 | J11: =IFERROR(VALUE(LEFT(F11,FIND("/",F11)-1))-VALUE(LEFT(B11,FIND("/",B11)-1)),"N/A") -> 1
A12: medium-003 | B12: 10/10 | C12: 0 | D12: 11.8 | E12: 0.00161175 | F12: 10/10 | G12: 0 | H12: 52.6 | I12: 0.02618126 | J12: =IFERROR(VALUE(LEFT(F12,FIND("/",F12)-1))-VALUE(LEFT(B12,FIND("/",B12)-1)),"N/A") -> 0
A13: medium-004 | B13: 6/9 | C13: 0 | D13: 11.4 | E13: 0.001621 | F13: 8/9 | G13: 1 | H13: 40.2 | I13: 0.03474044 | J13: =IFERROR(VALUE(LEFT(F13,FIND("/",F13)-1))-VALUE(LEFT(B13,FIND("/",B13)-1)),"N/A") -> 2
A14: medium-005 | B14: 9/10 | C14: 0 | D14: 11.9 | E14: 0.001886625 | F14: 10/10 | G14: 1 | H14: 45.4 | I14: 0.020369785 | J14: =IFERROR(VALUE(LEFT(F14,FIND("/",F14)-1))-VALUE(LEFT(B14,FIND("/",B14)-1)),"N/A") -> 1
A15: hard-001 | B15: 10/14 | C15: 0 | D15: 13.9 | E15: 0.002246375 | F15: 13/14 | G15: 1 | H15: 49.5 | I15: 0.020648185 | J15: =IFERROR(VALUE(LEFT(F15,FIND("/",F15)-1))-VALUE(LEFT(B15,FIND("/",B15)-1)),"N/A") -> 3
A16: hard-002 | B16: 11/14 | C16: 0 | D16: 13.4 | E16: 0.002767125 | F16: 11/14 | G16: 0 | H16: 36.3 | I16: 0.013974805 | J16: =IFERROR(VALUE(LEFT(F16,FIND("/",F16)-1))-VALUE(LEFT(B16,FIND("/",B16)-1)),"N/A") -> 0
... A19: hard-005 | B19: not reached | C19: 5 | D19: 43.1 | E19: 0.048179525 | F19: validator error | G19: 2 | H19: 72.1 | I19: 0.061791775 | J19: =IFERROR(VALUE(LEFT(F19,FIND("/",F19)-1))-VALUE(LEFT(B19,FIND("/",B19)-1)),"N/A") -> N/A
A20: TOTAL | B20: 109/135 (1 not reached) | C20: =SUM(C5:C19) -> 6 | D20: =SUM(D5:D19) -> 220.1 | E20: =SUM(E5:E19) -> 0.08389765 | F20: 111/121 (2 technical errors) | G20: =SUM(G5:G19) -> 8 | H20: =SUM(H5:H19) -> 610 | I20: =SUM(I5:I19) -> 0.32297659 | J20: =SUM(J5:J19) -> 10

Sheet Summary
A1: AIPyCraft paired experiment summary
A4: Model pairing | B4: Tasks | C4: Off score | D4: On score | E4: Effect | F4: Off regens | G4: On regens | H4: Off total time (min) | I4: On total time (min) | J4: Off cost (USD) | K4: On cost (USD)
A5: gpt-5-mini (low) → gpt-5.4-mini (low) | B5: 15 | C5: 109/135 (1 not reached) | D5: 130/149 | E5: ='5mini - 5.4mini'!J20 -> 11 | F5: ='5mini - 5.4mini'!C20 -> 6 | G5: ='5mini - 5.4mini'!G20 -> 15 | H5: ='5mini - 5.4mini'!D20 -> 220.1 | I5: ='5mini - 5.4mini'!H20 -> 229.2 | J5: ='5mini - 5.4mini'!E20 -> 0.08389765 | K5: ='5mini - 5.4mini'!I20 -> 0.29954375
A6: gpt-5.4-mini (low) → gpt-5.4-mini (low) | B6: 15 | C6: 130/149 | D6: 132/149 | E6: ='5.4mini - 5.4mini'!J20 -> 2 | F6: ='5.4mini - 5.4mini'!C20 -> 1 | G6: ='5.4mini - 5.4mini'!G20 -> 2 | H6: ='5.4mini - 5.4mini'!D20 -> 191.8 | I6: ='5.4mini - 5.4mini'!H20 -> 193.1 | J6: ='5.4mini - 5.4mini'!E20 -> 0.063906375 | K6: ='5.4mini - 5.4mini'!I20 -> 0.15765308
A7: gpt-5.4-mini (low) → gpt-5.6-sol (medium) | B7: 15 | C7: ='5.4mini - 5.6sol'!B20 -> 130/149 | D7: ='5.4mini - 5.6sol'!F20 -> 143/149 | E7: ='5.4mini - 5.6sol'!J20 -> 13 | F7: ='5.4mini - 5.6sol'!C20 -> 1 | G7: ='5.4mini - 5.6sol'!G20 -> 6 | H7: ='5.4mini - 5.6sol'!D20 -> 191.8 | I7: ='5.4mini - 5.6sol'!H20 -> 196.7 | J7: ='5.4mini - 5.6sol'!E20 -> 0.063906375 | K7: ='5.4mini - 5.6sol'!I20 -> 0.35088662
A8: claude-haiku-4.5 (medium) → claude-sonnet-5 (medium) | B8: 15 | C8: 135/149 | D8: 137/149 | E8: ='Haiku4.5 - Sonnet5'!J20 -> 2 | F8: ='Haiku4.5 - Sonnet5'!C20 -> 6 | G8: ='Haiku4.5 - Sonnet5'!G20 -> 5 | H8: ='Haiku4.5 - Sonnet5'!D20 -> 251.6 | I8: ='Haiku4.5 - Sonnet5'!H20 -> 232.9 | J8: ='Haiku4.5 - Sonnet5'!E20 -> 0.804802 | K8: ='Haiku4.5 - Sonnet5'!I20 -> 1.351965
A9: z-ai/glm-5.2 (high) → gpt-5.4-mini (medium) | B9: 15 | C9: 140/149 | D9: 141/149 | E9: ='GLM5.2 - 5.4mini'!J20 -> 1 | F9: ='GLM5.2 - 5.4mini'!C20 -> 1 | G9: ='GLM5.2 - 5.4mini'!G20 -> 1 | H9: ='GLM5.2 - 5.4mini'!D20 -> 252.9 | I9: ='GLM5.2 - 5.4mini'!H20 -> 255.6 | J9: ='GLM5.2 - 5.4mini'!E20 -> 0.64373116 | K9: ='GLM5.2 - 5.4mini'!I20 -> 0.95337336
